Workbook

Sheet Pet
A1: 魔宠id | B1: 魔宠名称 | C1: (nouse)备注 | D1: 品质 | E1: (nouse)策划备注 | F1: 模型id | G1: 魔宠列表头像 | H1: 获得背景 | I1: 获得立绘 | J1: 是否弹窗 | K1: 激活角色头像 | L1: 是否弹窗
A2: id.p | B2: name | C2: desc999 | D2: quality | E2: desc999 | F2: monsterId | G2: pic | H2: getBg | I2: getPic | J2: getShow | K2: headRole | L2: hide
A3: number | B3: string | C3: string | D3: number | E3: string | F3: number | G3: string | H3: string | I3: string | J3: number | K3: number | L3: number
A4: 6082 | B4: 雷电法王 | D4: 5 | E4: SR-闪电 | F4: 6082 | G4: ="pet/"&G$2&"/"&F4 -> pet/pic/6082 | H4: pet/getBg/sha | I4: pet/getPic/6082 | J4: =IF(D4=8,1,0) -> 0 | K4: 51200 | L4: 0
A5: 6022 | B5: 拳斗熊 | D5: 8 | E5: SSR-物理 | F5: 6022 | G5: ="pet/"&G$2&"/"&F5 -> pet/pic/6022 | H5: pet/getBg/huo | I5: pet/getPic/6022 | J5: =IF(D5=8,1,0) -> 1 | K5: 51201 | L5: 0
A6: 5030 | B6: 沙虫 | D6: 5 | E6: 无 | F6: 5030 | G6: ="pet/"&G$2&"/"&F6 -> pet/pic/5030 | J6: =IF(D6=8,1,0) -> 0 | K6: 51202 | L6: 1
A7: 5040 | B7: 炎龙 | D7: 4 | E7: R-火焰 | F7: 5040 | G7: ="pet/"&G$2&"/"&F7 -> pet/pic/5040 | J7: =IF(D7=8,1,0) -> 0 | K7: 51203 | L7: 0
A8: 5050 | B8: 半兽人 | D8: 4 | E8: R-攻击 | F8: 5050 | G8: ="pet/"&G$2&"/"&F8 -> pet/pic/5050 | J8: =IF(D8=8,1,0) -> 0 | K8: 51204 | L8: 0
A9: 5010 | B9: 树精 | D9: 4 | E9: R-近战 | F9: 5010 | G9: ="pet/"&G$2&"/"&F9 -> pet/pic/5010 | J9: =IF(D9=8,1,0) -> 0 | K9: 51205 | L9: 0
A10: 5020 | B10: 旅行鼠 | D10: 4 | E10: R-投射物 | F10: 5020 | G10: ="pet/"&G$2&"/"&F10 -> pet/pic/5020 | J10: =IF(D10=8,1,0) -> 0 | K10: 51206 | L10: 0
A11: 5060 | B11: 幽魂 | D11: 4 | E11: R-混沌 | F11: 5060 | G11: ="pet/"&G$2&"/"&F11 -> pet/pic/5060 | J11: =IF(D11=8,1,0) -> 0 | K11: 51207 | L11: 0
A12: 7022 | B12: 蕾朵 | D12: 8 | E12: SSR-法术 | F12: 7022 | G12: ="pet/"&G$2&"/"&F12 -> pet/pic/7022 | H12: pet/getBg/cao | I12: pet/getPic/7022 | J12: =IF(D12=8,1,0) -> 1 | K12: 51208 | L12: 0
A13: 6012 | B13: 冰虫骑士 | D13: 5 | E13: SR-物理 | F13: 6012 | G13: ="pet/"&G$2&"/"&F13 -> pet/pic/6012 | H13: pet/getBg/bing | I13: pet/getPic/6012 | J13: =IF(D13=8,1,0) -> 0 | K13: 51209 | L13: 0
A14: 6052 | B14: 猫浪人 | D14: 5 | E14: SR-攻击 | F14: 6052 | G14: ="pet/"&G$2&"/"&F14 -> pet/pic/6052 | H14: pet/getBg/shui | I14: pet/getPic/6052 | J14: =IF(D14=8,1,0) -> 0 | K14: 51210 | L14: 0
A15: 6042 | B15: 射击仙人 | D15: 5 | E15: SR-投射物 | F15: 6042 | G15: ="pet/"&G$2&"/"&F15 -> pet/pic/6042 | H15: pet/getBg/sha | I15: pet/getPic/6042 | J15: =IF(D15=8,1,0) -> 0 | K15: 51211 | L15: 0
A16: 6062 | B16: 咒术魔偶 | D16: 5 | E16: SR-混沌 | F16: 6062 | G16: ="pet/"&G$2&"/"&F16 -> pet/pic/6062 | H16: pet/getBg/an | I16: pet/getPic/6062 | J16: =IF(D16=8,1,0) -> 0 | K16: 51212 | L16: 0
A17: 6092 | B17: 剧团魔影 | D17: 5 | E17: SR-火焰 | F17: 6092 | G17: ="pet/"&G$2&"/"&F17 -> pet/pic/6092 | H17: pet/getBg/an | I17: pet/getPic/6092 | J17: =IF(D17=8,1,0) -> 0 | K17: 51213 | L17: 0
A18: 6032 | B18: 蜂行者 | D18: 5 | E18: SR-近战 | F18: 6032 | G18: ="pet/"&G$2&"/"&F18 -> pet/pic/6032 | H18: pet/getBg/lei | I18: pet/getPic/6032 | J18: =IF(D18=8,1,0) -> 0 | K18: 51214 | L18: 0
A19: 6112 | B19: 蔷薇法师 | D19: 5 | E19: SR-法术 | F19: 6112 | G19: ="pet/"&G$2&"/"&F19 -> pet/pic/6112 | H19: pet/getBg/cao | I19: pet/getPic/6112 | J19: =IF(D19=8,1,0) -> 0 | K19: 51215 | L19: 0
A20: 7032 | B20: 熔炉魔灵 | D20: 8 | E20: SSR-火焰 | F20: 7032 | G20: ="pet/"&G$2&"/"&F20 -> pet/pic/7032 | H20: pet/getBg/huo | I20: pet/getPic/7032 | J20: =IF(D20=8,1,0) -> 1 | K20: 51216 | L20: 0
A21: 7052 | B21: 雷暴元素 | D21: 8 | E21: SSR-闪电 | F21: 7052 | G21: ="pet/"&G$2&"/"&F21 -> pet/pic/7052 | H21: pet/getBg/sha | I21: pet/getPic/7052 | J21: =IF(D21=8,1,0) -> 1 | K21: 51217 | L21: 0
A22: 5070 | B22: 麒麟 | D22: 4 | E22: R-闪电 | F22: 5070 | G22: ="pet/"&G$2&"/"&F22 -> pet/pic/5070 | J22: =IF(D22=8,1,0) -> 0 | K22: 51218 | L22: 0
A23: 5080 | B23: 冰球 | D23: 4 | E23: R-冰冷 | F23: 5080 | G23: ="pet/"&G$2&"/"&F23 -> pet/pic/5080 | J23: =IF(D23=8,1,0) -> 0 | K23: 51219 | L23: 0
A24: 5090 | B24: 恶魔 | D24: 4 | E24: R-法术 | F24: 5090 | G24: ="pet/"&G$2&"/"&F24 -> pet/pic/5090 | J24: =IF(D24=8,1,0) -> 0 | K24: 51220 | L24: 0
A25: 5100 | B25: 章鱼 | D25: 4 | E25: R-物理 | F25: 5100 | G25: ="pet/"&G$2&"/"&F25 -> pet/pic/5100 | J25: =IF(D25=8,1,0) -> 0 | K25: 51221 | L25: 0
A26: 7012 | B26: 珠泪使者 | D26: 8 | E26: SSR-冰冷 | F26: 7012 | G26: ="pet/"&G$2&"/"&F26 -> pet/pic/7012 | H26: pet/getBg/shui | I26: pet/getPic/7012 | J26: =IF(D26=8,1,0) -> 1 | K26: 51222 | L26: 0
A27: 7062 | B27: 破冰战甲 | D27: 8 | E27: SSR-近战 | F27: 7062 | G27: ="pet/"&G$2&"/"&F27 -> pet/pic/7062 | H27: pet/getBg/bing | I27: pet/getPic/7062 | J27: =IF(D27=8,1,0) -> 1 | K27: 51223 | L27: 0
A28: 7042 | B28: 混沌魔猿 | D28: 8 | E28: SSR-混沌 | F28: 7042 | G28: ="pet/"&G$2&"/"&F28 -> pet/pic/7042 | H28: pet/getBg/an | I28: pet/getPic/7042 | J28: =IF(D28=8,1,0) -> 1 | K28: 51224 | L28: 0
A29: 7082 | B29: 烈焰机甲 | D29: 8 | E29: SSR-投射物 | F29: 7082 | G29: ="pet/"&G$2&"/"&F29 -> pet/pic/7082 | H29: pet/getBg/huo | I29: pet/getPic/7082 | J29: =IF(D29=8,1,0) -> 1 | K29: 51225 | L29: 0
A30: 7072 | B30: 利爪冰狼 | D30: 8 | E30: SSR-攻击 | F30: 7072 | G30: ="pet/"&G$2&"/"&F30 -> pet/pic/7072 | H30: pet/getBg/bing | I30: pet/getPic/7072 | J30: =IF(D30=8,1,0) -> 1 | K30: 51226 | L30: 0
A31: 6142 | B31: 暴鲤龙 | D31: 5 | E31: SR-冰冷 | F31: 6142 | G31: ="pet/"&G$2&"/"&F31 -> pet/pic/6142 | H31: pet/getBg/bing | I31: pet/getPic/6142 | J31: =IF(D31=8,1,0) -> 0 | K31: 51227 | L31: 0

Sheet PetStar
A1: 主键id | B1: (nouse)策划说明 | C1: 魔宠Id | D1: 星级 | E1: 升星消耗碎片 | F1: 描述（改程序读表） | G1: 词缀id | H1: 词缀值 | I1: 被动表id | J1: 提供属性-启用加属性 | K1: (nouse)策划备注 | L1: (nouse)属性1 | M1: (nouse)属性1值 | N1: (nouse)属性2 | O1: (nouse)属性2值 | P1: (nouse)属性3 | Q1: (nouse)属性3值 | R1: (nouse)词缀1 | S1: (nouse)词缀1值 | T1: (nouse)词缀2 | U1: (nouse)词缀2值 | V1: (nouse)词缀3 | W1: (nouse)词缀3值 | X1: (nouse)词缀4 | Y1: (nouse)词缀4值 | Z1: (nouse)特技1 | AA1: (nouse)特技2 | AB1: (nouse)属性1id | AC1: (nouse)属性2id | AD1: (nouse)属性3id | AE1: (nouse)辅助1 | AF1: (nouse)辅助2 | AG1: (nouse)辅助3 | AH1: (nouse)词缀1id | AI1: (nouse)词缀2id | AJ1: (nouse)词缀3id | AK1: (nouse)词缀4id | AL1: (nouse)辅助1 | AM1: (nouse)辅助2 | AN1: (nouse)辅助3 | AO1: (nouse)辅助4 | AP1: (nouse)特技1id | AQ1: (nouse)特技2id
A2: id.p | B2: desc999 | C2: pet | D2: star | E2: pieceCost | F2: desc | G2: skillAffix | H2: affixValue | I2: stunt | J2: attr | K2: desc99 | L2: desc98 | M2: desc96 | N2: desc95 | O2: desc93 | P2: desc92 | Q2: desc90 | R2: desc89 | S2: desc88 | T2: desc87 | U2: desc86 | V2: desc85 | W2: desc84 | X2: desc83 | Y2: desc82 | Z2: desc81 | AA2: desc80 | AB2: desc79 | AC2: desc78 | AD2: desc77 | AE2: desc76 | AF2: desc75 | AG2: desc74 | AH2: desc73 | AI2: desc72 | AJ2: desc71 | AK2: desc70 | AL2: desc69 | AM2: desc68 | AN2: desc67 | AO2: desc66 | AP2: desc65 | AQ2: desc64
A3: number | B3: string | C3: number | D3: number | E3: object | F3: string | G3: numberArr | H3: object | I3: numberArr | J3: object | K3: string | L3: string | M3: string | N3: string | O3: string | P3: string | Q3: string | R3: string | S3: string | T3: string | U3: string | V3: string | W3: string | X3: string | Y3: string | Z3: string | AA3: string | AB3: string | AC3: string | AD3: string | AE3: string | AF3: string | AG3: string | AH3: string | AI3: string | AJ3: string | AK3: string | AL3: string | AM3: string | AN3: string | AO3: string | AP3: string | AQ3: string
A4: =C4*10+D4 -> 60820 | B4: 雷电法老王-星级0 | C4: 6082 | D4: 0 | E4: ="[["&C4+10000&",1]]" -> [[16082,1]] | G4: =_xlfn.TEXTJOIN("|",TRUE,AH4:AJ4) | H4: =IF(R4="","",_xlfn.CONCAT("[",_xlfn.TEXTJOIN(",",TRUE,AL4:AO4),"]")) | I4: =_xlfn.TEXTJOIN("|",TRUE,AP4:AQ4) | J4: =IF(AB4="","",_xlfn.CONCAT("[",_xlfn.TEXTJOIN(",",TRUE,AE4:AG4),"]")) -> [[10306,0.1],[11010,0.1]] | K4: =_xlfn.XLOOKUP(C4,Pet!A:A,Pet!E:E) -> SR-闪电 | L4: 闪电伤害提高 | M4: 0.1 | N4: 感电效果比例 | O4: 0.1 | AB4: =IFERROR(IF(L4<>"",_xlfn.XLOOKUP(L4,[1]AttributeName!$C:$C,[1]AttributeName!$B:$B,""),""),"") -> 10306 | AC4: =IFERROR(IF(N4<>"",_xlfn.XLOOKUP(N4,[1]AttributeName!$C:$C,[1]AttributeName!$B:$B,""),""),"") -> 11010 | AD4: =IFERROR(IF(P4<>"",_xlfn.XLOOKUP(P4,[1]AttributeName!$C:$C,[1]AttributeName!$B:$B,""),""),"") | AE4: =IF(AB4="","",_xlfn.CONCAT("[",AB4,",",M4,"]")) -> [10306,0.1] | AF4: =IF(AC4="","",_xlfn.CONCAT("[",AC4,",",O4,"]")) -> [11010,0.1] | AG4: =IF(AD4="","",_xlfn.CONCAT("[",AD4,",",Q4,"]")) | AH4: =IFERROR(IF(R4<>"",_xlfn.XLOOKUP(R4,[1]ModifierDes!$B:$B,[1]ModifierDes!$A:$A,""),""),"") | AI4: =IFERROR(IF(T4<>"",_xlfn.XLOOKUP(T4,[1]ModifierDes!$B:$B,[1]ModifierDes!$A:$A,""),""),"") | AJ4: =IFERROR(IF(V4<>"",_xlfn.XLOOKUP(V4,[1]ModifierDes!$B:$B,[1]ModifierDes!$A:$A,""),""),"") | AK4: =IFERROR(IF(X4<>"",_xlfn.XLOOKUP(X4,[1]ModifierDes!$B:$B,[1]ModifierDes!$A:$A,""),""),"") | AL4: =IF(S4="","",_xlfn.CONCAT("[",S4,"]")) | AM4: =IF(U4="","",_xlfn.CONCAT("[",U4,"]")) | AN4: =IF(W4="","",_xlfn.CONCAT("[",W4,"]")) | AO4: =IF(Y4="","",_xlfn.CONCAT("[",Y4,"]")) | AP4: =IFERROR(IF(Z4<>"",_xlfn.XLOOKUP(Z4,[1]StuntDes!$B:$B,[1]StuntDes!$A:$A,""),""),"") | AQ4: =IFERROR(IF(AA4<>"",_xlfn.XLOOKUP(AA4,[1]StuntDes!$B:$B,[1]StuntDes!$A:$A,""),""),"")
A5: =C5*10+D5 -> 60821 | B5: 雷电法老王-星级1 | C5: 6082 | D5: 1 | E5: ="[["&C5+10000&",1]]" -> [[16082,1]] | G5: =_xlfn.TEXTJOIN("|",TRUE,AH5:AJ5) | H5: =IF(R5="","",_xlfn.CONCAT("[",_xlfn.TEXTJOIN(",",TRUE,AL5:AO5),"]")) | I5: =_xlfn.TEXTJOIN("|",TRUE,AP5:AQ5) | J5: =IF(AB5="","",_xlfn.CONCAT("[",_xlfn.TEXTJOIN(",",TRUE,AE5:AG5),"]")) -> [[10306,0.25],[11010,0.1]] | K5: =_xlfn.XLOOKUP(C5,Pet!A:A,Pet!E:E) -> SR-闪电 | L5: 闪电伤害提高 | M5: 0.25 | N5: 感电效果比例 | O5: 0.1 | AB5: =IFERROR(IF(L5<>"",_xlfn.XLOOKUP(L5,[1]AttributeName!$C:$C,[1]AttributeName!$B:$B,""),""),"") -> 10306 | AC5: =IFERROR(IF(N5<>"",_xlfn.XLOOKUP(N5,[1]AttributeName!$C:$C,[1]AttributeName!$B:$B,""),""),"") -> 11010 | AD5: =IFERROR(IF(P5<>"",_xlfn.XLOOKUP(P5,[1]AttributeName!$C:$C,[1]AttributeName!$B:$B,""),""),"") | AE5: =IF(AB5="","",_xlfn.CONCAT("[",AB5,",",M5,"]")) -> [10306,0.25] | AF5: =IF(AC5="","",_xlfn.CONCAT("[",AC5,",",O5,"]")) -> [11010,0.1] | AG5: =IF(AD5="","",_xlfn.CONCAT("[",AD5,",",Q5,"]")) | AH5: =IFERROR(IF(R5<>"",_xlfn.XLOOKUP(R5,[1]ModifierDes!$B:$B,[1]ModifierDes!$A:$A,""),""),"") | AI5: =IFERROR(IF(T5<>"",_xlfn.XLOOKUP(T5,[1]ModifierDes!$B:$B,[1]ModifierDes!$A:$A,""),""),"") | AJ5: =IFERROR(IF(V5<>"",_xlfn.XLOOKUP(V5,[1]ModifierDes!$B:$B,[1]ModifierDes!$A:$A,""),""),"") | AK5: =IFERROR(IF(X5<>"",_xlfn.XLOOKUP(X5,[1]ModifierDes!$B:$B,[1]ModifierDes!$A:$A,""),""),"") | AL5: =IF(S5="","",_xlfn.CONCAT("[",S5,"]")) | AM5: =IF(U5="","",_xlfn.CONCAT("[",U5,"]")) | AN5: =IF(W5="","",_xlfn.CONCAT("[",W5,"]")) | AO5: =IF(Y5="","",_xlfn.CONCAT("[",Y5,"]")) | AP5: =IFERROR(IF(Z5<>"",_xlfn.XLOOKUP(Z5,[1]StuntDes!$B:$B,[1]StuntDes!$A:$A,""),""),"") | AQ5: =IFERROR(IF(AA5<>"",_xlfn.XLOOKUP(AA5,[1]StuntDes!$B:$B,[1]StuntDes!$A:$A,""),""),"")
A6: =C6*10+D6 -> 60822 | B6: 雷电法老王-星级2 | C6: 6082 | D6: 2 | E6: ="[["&C6+10000&",1]]" -> [[16082,1]] | G6: =_xlfn.TEXTJOIN("|",TRUE,AH6:AJ6) | H6: =IF(R6="","",_xlfn.CONCAT("[",_xlfn.TEXTJOIN(",",TRUE,AL6:AO6),"]")) | I6: =_xlfn.TEXTJOIN("|",TRUE,AP6:AQ6) | J6: =IF(AB6="","",_xlfn.CONCAT("[",_xlfn.TEXTJOIN(",",TRUE,AE6:AG6),"]")) -> [[10306,0.25],[11010,0.3]] | K6: =_xlfn.XLOOKUP(C6,Pet!A:A,Pet!E:E) -> SR-闪电 | L6: 闪电伤害提高 | M6: 0.25 | N6: 感电效果比例 | O6: 0.3 | AB6: =IFERROR(IF(L6<>"",_xlfn.XLOOKUP(L6,[1]AttributeName!$C:$C,[1]AttributeName!$B:$B,""),""),"") -> 10306 | AC6: =IFERROR(IF(N6<>"",_xlfn.XLOOKUP(N6,[1]AttributeName!$C:$C,[1]AttributeName!$B:$B,""),""),"") -> 11010 | AD6: =IFERROR(IF(P6<>"",_xlfn.XLOOKUP(P6,[1]AttributeName!$C:$C,[1]AttributeName!$B:$B,""),""),"") | AE6: =IF(AB6="","",_xlfn.CONCAT("[",AB6,",",M6,"]")) -> [10306,0.25] | AF6: =IF(AC6="","",_xlfn.CONCAT("[",AC6,",",O6,"]")) -> [11010,0.3] | AG6: =IF(AD6="","",_xlfn.CONCAT("[",AD6,",",Q6,"]")) | AH6: =IFERROR(IF(R6<>"",_xlfn.XLOOKUP(R6,[1]ModifierDes!$B:$B,[1]ModifierDes!$A:$A,""),""),"") | AI6: =IFERROR(IF(T6<>"",_xlfn.XLOOKUP(T6,[1]ModifierDes!$B:$B,[1]ModifierDes!$A:$A,""),""),"") | AJ6: =IFERROR(IF(V6<>"",_xlfn.XLOOKUP(V6,[1]ModifierDes!$B:$B,[1]ModifierDes!$A:$A,""),""),"") | AK6: =IFERROR(IF(X6<>"",_xlfn.XLOOKUP(X6,[1]ModifierDes!$B:$B,[1]ModifierDes!$A:$A,""),""),"") | AL6: =IF(S6="","",_xlfn.CONCAT("[",S6,"]")) | AM6: =IF(U6="","",_xlfn.CONCAT("[",U6,"]")) | AN6: =IF(W6="","",_xlfn.CONCAT("[",W6,"]")) | AO6: =IF(Y6="","",_xlfn.CONCAT("[",Y6,"]")) | AP6: =IFERROR(IF(Z6<>"",_xlfn.XLOOKUP(Z6,[1]StuntDes!$B:$B,[1]StuntDes!$A:$A,""),""),"") | AQ6: =IFERROR(IF(AA6<>"",_xlfn.XLOOKUP(AA6,[1]StuntDes!$B:$B,[1]StuntDes!$A:$A,""),""),"")
A7: =C7*10+D7 -> 60823 | B7: 雷电法老王-星级3 | C7: 6082 | D7: 3 | E7: ="[["&C7+10000&",1]]" -> [[16082,1]] | G7: =_xlfn.TEXTJOIN("|",TRUE,AH7:AJ7) | H7: =IF(R7="","",_xlfn.CONCAT("[",_xlfn.TEXTJOIN(",",TRUE,AL7:AO7),"]")) | I7: =_xlfn.TEXTJOIN("|",TRUE,AP7:AQ7) | J7: =IF(AB7="","",_xlfn.CONCAT("[",_xlfn.TEXTJOIN(",",TRUE,AE7:AG7),"]")) -> [[10306,0.25],[11010,0.3],[10300,0.12]] | K7: =_xlfn.XLOOKUP(C7,Pet!A:A,Pet!E:E) -> SR-闪电 | L7: 闪电伤害提高 | M7: 0.25 | N7: 感电效果比例 | O7: 0.3 | P7: 全局伤害提高 | Q7: 0.12 | AB7: =IFERROR(IF(L7<>"",_xlfn.XLOOKUP(L7,[1]AttributeName!$C:$C,[1]AttributeName!$B:$B,""),""),"") -> 10306 | AC7: =IFERROR(IF(N7<>"",_xlfn.XLOOKUP(N7,[1]AttributeName!$C:$C,[1]AttributeName!$B:$B,""),""),"") -> 11010 | AD7: =IFERROR(IF(P7<>"",_xlfn.XLOOKUP(P7,[1]AttributeName!$C:$C,[1]AttributeName!$B:$B,""),""),"") -> 10300 | AE7: =IF(AB7="","",_xlfn.CONCAT("[",AB7,",",M7,"]")) -> [10306,0.25] | AF7: =IF(AC7="","",_xlfn.CONCAT("[",AC7,",",O7,"]")) -> [11010,0.3] | AG7: =IF(AD7="","",_xlfn.CONCAT("[",AD7,",",Q7,"]")) -> [10300,0.12] | AH7: =IFERROR(IF(R7<>"",_xlfn.XLOOKUP(R7,[1]ModifierDes!$B:$B,[1]ModifierDes!$A:$A,""),""),"") | AI7: =IFERROR(IF(T7<>"",_xlfn.XLOOKUP(T7,[1]ModifierDes!$B:$B,[1]ModifierDes!$A:$A,""),""),"") | AJ7: =IFERROR(IF(V7<>"",_xlfn.XLOOKUP(V7,[1]ModifierDes!$B:$B,[1]ModifierDes!$A:$A,""),""),"") | AK7: =IFERROR(IF(X7<>"",_xlfn.XLOOKUP(X7,[1]ModifierDes!$B:$B,[1]ModifierDes!$A:$A,""),""),"") | AL7: =IF(S7="","",_xlfn.CONCAT("[",S7,"]")) | AM7: =IF(U7="","",_xlfn.CONCAT("[",U7,"]")) | AN7: =IF(W7="","",_xlfn.CONCAT("[",W7,"]")) | AO7: =IF(Y7="","",_xlfn.CONCAT("[",Y7,"]")) | AP7: =IFERROR(IF(Z7<>"",_xlfn.XLOOKUP(Z7,[1]StuntDes!$B:$B,[1]StuntDes!$A:$A,""),""),"") | AQ7: =IFERROR(IF(AA7<>"",_xlfn.XLOOKUP(AA7,[1]StuntDes!$B:$B,[1]StuntDes!$A:$A,""),""),"")
A8: =C8*10+D8 -> 60824 | B8: 雷电法老王-星级4 | C8: 6082 | D8: 4 | E8: ="[["&C8+10000&",1]]" -> [[16082,1]] | G8: =_xlfn.TEXTJOIN("|",TRUE,AH8:AJ8) | H8: =IF(R8="","",_xlfn.CONCAT("[",_xlfn.TEXTJOIN(",",TRUE,AL8:AO8),"]")) | I8: =_xlfn.TEXTJOIN("|",TRUE,AP8:AQ8) | J8: =IF(AB8="","",_xlfn.CONCAT("[",_xlfn.TEXTJOIN(",",TRUE,AE8:AG8),"]")) -> [[10306,0.39],[11010,0.3],[10300,0.12]] | K8: =_xlfn.XLOOKUP(C8,Pet!A:A,Pet!E:E) -> SR-闪电 | L8: 闪电伤害提高 | M8: 0.39 | N8: 感电效果比例 | O8: 0.3 | P8: 全局伤害提高 | Q8: 0.12 | AB8: =IFERROR(IF(L8<>"",_xlfn.XLOOKUP(L8,[1]AttributeName!$C:$C,[1]AttributeName!$B:$B,""),""),"") -> 10306 | AC8: =IFERROR(IF(N8<>"",_xlfn.XLOOKUP(N8,[1]AttributeName!$C:$C,[1]AttributeName!$B:$B,""),""),"") -> 11010 | AD8: =IFERROR(IF(P8<>"",_xlfn.XLOOKUP(P8,[1]AttributeName!$C:$C,[1]AttributeName!$B:$B,""),""),"") -> 10300 | AE8: =IF(AB8="","",_xlfn.CONCAT("[",AB8,",",M8,"]")) -> [10306,0.39] | AF8: =IF(AC8="","",_xlfn.CONCAT("[",AC8,",",O8,"]")) -> [11010,0.3] | AG8: =IF(AD8="","",_xlfn.CONCAT("[",AD8,",",Q8,"]")) -> [10300,0.12] | AH8: =IFERROR(IF(R8<>"",_xlfn.XLOOKUP(R8,[1]ModifierDes!$B:$B,[1]ModifierDes!$A:$A,""),""),"") | AI8: =IFERROR(IF(T8<>"",_xlfn.XLOOKUP(T8,[1]ModifierDes!$B:$B,[1]ModifierDes!$A:$A,""),""),"") | AJ8: =IFERROR(IF(V8<>"",_xlfn.XLOOKUP(V8,[1]ModifierDes!$B:$B,[1]ModifierDes!$A:$A,""),""),"") | AK8: =IFERROR(IF(X8<>"",_xlfn.XLOOKUP(X8,[1]ModifierDes!$B:$B,[1]ModifierDes!$A:$A,""),""),"") | AL8: =IF(S8="","",_xlfn.CONCAT("[",S8,"]")) | AM8: =IF(U8="","",_xlfn.CONCAT("[",U8,"]")) | AN8: =IF(W8="","",_xlfn.CONCAT("[",W8,"]")) | AO8: =IF(Y8="","",_xlfn.CONCAT("[",Y8,"]")) | AP8: =IFERROR(IF(Z8<>"",_xlfn.XLOOKUP(Z8,[1]StuntDes!$B:$B,[1]StuntDes!$A:$A,""),""),"") | AQ8: =IFERROR(IF(AA8<>"",_xlfn.XLOOKUP(AA8,[1]StuntDes!$B:$B,[1]StuntDes!$A:$A,""),""),"")
A9: =C9*10+D9 -> 60825 | B9: 雷电法老王-星级5 | C9: 6082 | D9: 5 | G9: =_xlfn.TEXTJOIN("|",TRUE,AH9:AJ9) | H9: =IF(R9="","",_xlfn.CONCAT("[",_xlfn.TEXTJOIN(",",TRUE,AL9:AO9),"]")) | I9: =_xlfn.TEXTJOIN("|",TRUE,AP9:AQ9) | J9: =IF(AB9="","",_xlfn.CONCAT("[",_xlfn.TEXTJOIN(",",TRUE,AE9:AG9),"]")) -> [[10306,0.39],[11010,0.62],[10300,0.12]] | K9: =_xlfn.XLOOKUP(C9,Pet!A:A,Pet!E:E) -> SR-闪电 | L9: 闪电伤害提高 | M9: 0.39 | N9: 感电效果比例 | O9: 0.62 | P9: 全局伤害提高 | Q9: 0.12 | AB9: =IFERROR(IF(L9<>"",_xlfn.XLOOKUP(L9,[1]AttributeName!$C:$C,[1]AttributeName!$B:$B,""),""),"") -> 10306 | AC9: =IFERROR(IF(N9<>"",_xlfn.XLOOKUP(N9,[1]AttributeName!$C:$C,[1]AttributeName!$B:$B,""),""),"") -> 11010 | AD9: =IFERROR(IF(P9<>"",_xlfn.XLOOKUP(P9,[1]AttributeName!$C:$C,[1]AttributeName!$B:$B,""),""),"") -> 10300 | AE9: =IF(AB9="","",_xlfn.CONCAT("[",AB9,",",M9,"]")) -> [10306,0.39] | AF9: =IF(AC9="","",_xlfn.CONCAT("[",AC9,",",O9,"]")) -> [11010,0.62] | AG9: =IF(AD9="","",_xlfn.CONCAT("[",AD9,",",Q9,"]")) -> [10300,0.12] | AH9: =IFERROR(IF(R9<>"",_xlfn.XLOOKUP(R9,[1]ModifierDes!$B:$B,[1]ModifierDes!$A:$A,""),""),"") | AI9: =IFERROR(IF(T9<>"",_xlfn.XLOOKUP(T9,[1]ModifierDes!$B:$B,[1]ModifierDes!$A:$A,""),""),"") | AJ9: =IFERROR(IF(V9<>"",_xlfn.XLOOKUP(V9,[1]ModifierDes!$B:$B,[1]ModifierDes!$A:$A,""),""),"") | AK9: =IFERROR(IF(X9<>"",_xlfn.XLOOKUP(X9,[1]ModifierDes!$B:$B,[1]ModifierDes!$A:$A,""),""),"") | AL9: =IF(S9="","",_xlfn.CONCAT("[",S9,"]")) | AM9: =IF(U9="","",_xlfn.CONCAT("[",U9,"]")) | AN9: =IF(W9="","",_xlfn.CONCAT("[",W9,"]")) | AO9: =IF(Y9="","",_xlfn.CONCAT("[",Y9,"]")) | AP9: =IFERROR(IF(Z9<>"",_xlfn.XLOOKUP(Z9,[1]StuntDes!$B:$B,[1]StuntDes!$A:$A,""),""),"") | AQ9: =IFERROR(IF(AA9<>"",_xlfn.XLOOKUP(AA9,[1]StuntDes!$B:$B,[1]StuntDes!$A:$A,""),""),"")
A10: =C10*10+D10 -> 60220 | B10: 拳斗熊-星级0 | C10: 6022 | D10: 0 | E10: ="[["&C10+10000&",1]]" -> [[16022,1]] | G10: =_xlfn.TEXTJOIN("|",TRUE,AH10:AJ10) -> 10124 | H10: =IF(R10="","",_xlfn.CONCAT("[",_xlfn.TEXTJOIN(",",TRUE,AL10:AO10),"]")) -> [[0.1]] | I10: =_xlfn.TEXTJOIN("|",TRUE,AP10:AQ10) | J10: =IF(AB10="","",_xlfn.CONCAT("[",_xlfn.TEXTJOIN(",",TRUE,AE10:AG10),"]")) -> [[10303,0.05]] | K10: =_xlfn.XLOOKUP(C10,Pet!A:A,Pet!E:E) -> SSR-物理 | L10: 物理伤害提高 | M10: 0.05 | R10: 物理伤害额外提高 | S10: 0.1 | AB10: =IFERROR(IF(L10<>"",_xlfn.XLOOKUP(L10,[1]AttributeName!$C:$C,[1]AttributeName!$B:$B,""),""),"") -> 10303 | AC10: =IFERROR(IF(N10<>"",_xlfn.XLOOKUP(N10,[1]AttributeName!$C:$C,[1]AttributeName!$B:$B,""),""),"") | AD10: =IFERROR(IF(P10<>"",_xlfn.XLOOKUP(P10,[1]AttributeName!$C:$C,[1]AttributeName!$B:$B,""),""),"") | AE10: =IF(AB10="","",_xlfn.CONCAT("[",AB10,",",M10,"]")) -> [10303,0.05] | AF10: =IF(AC10="","",_xlfn.CONCAT("[",AC10,",",O10,"]")) | AG10: =IF(AD10="","",_xlfn.CONCAT("[",AD10,",",Q10,"]")) | AH10: =IFERROR(IF(R10<>"",_xlfn.XLOOKUP(R10,[1]ModifierDes!$B:$B,[1]ModifierDes!$A:$A,""),""),"") -> 10124 | AI10: =IFERROR(IF(T10<>"",_xlfn.XLOOKUP(T10,[1]ModifierDes!$B:$B,[1]ModifierDes!$A:$A,""),""),"") | AJ10: =IFERROR(IF(V10<>"",_xlfn.XLOOKUP(V10,[1]ModifierDes!$B:$B,[1]ModifierDes!$A:$A,""),""),"") | AK10: =IFERROR(IF(X10<>"",_xlfn.XLOOKUP(X10,[1]ModifierDes!$B:$B,[1]ModifierDes!$A:$A,""),""),"") | AL10: =IF(S10="","",_xlfn.CONCAT("[",S10,"]")) -> [0.1] | AM10: =IF(U10="","",_xlfn.CONCAT("[",U10,"]")) | AN10: =IF(W10="","",_xlfn.CONCAT("[",W10,"]")) | AO10: =IF(Y10="","",_xlfn.CONCAT("[",Y10,"]")) | AP10: =IFERROR(IF(Z10<>"",_xlfn.XLOOKUP(Z10,[1]StuntDes!$B:$B,[1]StuntDes!$A:$A,""),""),"") | AQ10: =IFERROR(IF(AA10<>"",_xlfn.XLOOKUP(AA10,[1]StuntDes!$B:$B,[1]StuntDes!$A:$A,""),""),"")
A11: =C11*10+D11 -> 60221 | B11: 拳斗熊-星级1 | C11: 6022 | D11: 1 | E11: ="[["&C11+10000&",1]]" -> [[16022,1]] | G11: =_xlfn.TEXTJOIN("|",TRUE,AH11:AJ11) -> 10124 | H11: =IF(R11="","",_xlfn.CONCAT("[",_xlfn.TEXTJOIN(",",TRUE,AL11:AO11),"]")) -> [[0.15]] | I11: =_xlfn.TEXTJOIN("|",TRUE,AP11:AQ11) | J11: =IF(AB11="","",_xlfn.CONCAT("[",_xlfn.TEXTJOIN(",",TRUE,AE11:AG11),"]")) -> [[10303,0.05],[11055,0.1]] | K11: =_xlfn.XLOOKUP(C11,Pet!A:A,Pet!E:E) -> SSR-物理 | L11: 物理伤害提高 | M11: 0.05 | N11: 流血效果比例 | O11: 0.1 | R11: 物理伤害额外提高 | S11: 0.15 | AB11: =IFERROR(IF(L11<>"",_xlfn.XLOOKUP(L11,[1]AttributeName!$C:$C,[1]AttributeName!$B:$B,""),""),"") -> 10303 | AC11: =IFERROR(IF(N11<>"",_xlfn.XLOOKUP(N11,[1]AttributeName!$C:$C,[1]AttributeName!$B:$B,""),""),"") -> 11055 | AD11: =IFERROR(IF(P11<>"",_xlfn.XLOOKUP(P11,[1]AttributeName!$C:$C,[1]AttributeName!$B:$B,""),""),"") | AE11: =IF(AB11="","",_xlfn.CONCAT("[",AB11,",",M11,"]")) -> [10303,0.05] | AF11: =IF(AC11="","",_xlfn.CONCAT("[",AC11,",",O11,"]")) -> [11055,0.1] | AG11: =IF(AD11="","",_xlfn.CONCAT("[",AD11,",",Q11,"]")) | AH11: =IFERROR(IF(R11<>"",_xlfn.XLOOKUP(R11,[1]ModifierDes!$B:$B,[1]ModifierDes!$A:$A,""),""),"") -> 10124 | AI11: =IFERROR(IF(T11<>"",_xlfn.XLOOKUP(T11,[1]ModifierDes!$B:$B,[1]ModifierDes!$A:$A,""),""),"") | AJ11: =IFERROR(IF(V11<>"",_xlfn.XLOOKUP(V11,[1]ModifierDes!$B:$B,[1]ModifierDes!$A:$A,""),""),"") | AK11: =IFERROR(IF(X11<>"",_xlfn.XLOOKUP(X11,[1]ModifierDes!$B:$B,[1]ModifierDes!$A:$A,""),""),"") | AL11: =IF(S11="","",_xlfn.CONCAT("[",S11,"]")) -> [0.15] | AM11: =IF(U11="","",_xlfn.CONCAT("[",U11,"]")) | AN11: =IF(W11="","",_xlfn.CONCAT("[",W11,"]")) | AO11: =IF(Y11="","",_xlfn.CONCAT("[",Y11,"]")) | AP11: =IFERROR(IF(Z11<>"",_xlfn.XLOOKUP(Z11,[1]StuntDes!$B:$B,[1]StuntDes!$A:$A,""),""),"") | AQ11: =IFERROR(IF(AA11<>"",_xlfn.XLOOKUP(AA11,[1]StuntDes!$B:$B,[1]StuntDes!$A:$A,""),""),"")
A12: =C12*10+D12 -> 60222 | B12: 拳斗熊-星级2 | C12: 6022 | D12: 2 | E12: ="[["&C12+10000&",1]]" -> [[16022,1]] | G12: =_xlfn.TEXTJOIN("|",TRUE,AH12:AJ12) -> 10124 | H12: =IF(R12="","",_xlfn.CONCAT("[",_xlfn.TEXTJOIN(",",TRUE,AL12:AO12),"]")) -> [[0.2]] | I12: =_xlfn.TEXTJOIN("|",TRUE,AP12:AQ12) | J12: =IF(AB12="","",_xlfn.CONCAT("[",_xlfn.TEXTJOIN(",",TRUE,AE12:AG12),"]")) -> [[10303,0.1],[11055,0.1]] | K12: =_xlfn.XLOOKUP(C12,Pet!A:A,Pet!E:E) -> SSR-物理 | L12: 物理伤害提高 | M12: 0.1 | N12: 流血效果比例 | O12: 0.1 | R12: 物理伤害额外提高 | S12: 0.2 | AB12: =IFERROR(IF(L12<>"",_xlfn.XLOOKUP(L12,[1]AttributeName!$C:$C,[1]AttributeName!$B:$B,""),""),"") -> 10303 | AC12: =IFERROR(IF(N12<>"",_xlfn.XLOOKUP(N12,[1]AttributeName!$C:$C,[1]AttributeName!$B:$B,""),""),"") -> 11055 | AD12: =IFERROR(IF(P12<>"",_xlfn.XLOOKUP(P12,[1]AttributeName!$C:$C,[1]AttributeName!$B:$B,""),""),"") | AE12: =IF(AB12="","",_xlfn.CONCAT("[",AB12,",",M12,"]")) -> [10303,0.1] | AF12: =IF(AC12="","",_xlfn.CONCAT("[",AC12,",",O12,"]")) -> [11055,0.1] | AG12: =IF(AD12="","",_xlfn.CONCAT("[",AD12,",",Q12,"]")) | AH12: =IFERROR(IF(R12<>"",_xlfn.XLOOKUP(R12,[1]ModifierDes!$B:$B,[1]ModifierDes!$A:$A,""),""),"") -> 10124 | AI12: =IFERROR(IF(T12<>"",_xlfn.XLOOKUP(T12,[1]ModifierDes!$B:$B,[1]ModifierDes!$A:$A,""),""),"") | AJ12: =IFERROR(IF(V12<>"",_xlfn.XLOOKUP(V12,[1]ModifierDes!$B:$B,[1]ModifierDes!$A:$A,""),""),"") | AK12: =IFERROR(IF(X12<>"",_xlfn.XLOOKUP(X12,[1]ModifierDes!$B:$B,[1]ModifierDes!$A:$A,""),""),"") | AL12: =IF(S12="","",_xlfn.CONCAT("[",S12,"]")) -> [0.2] | AM12: =IF(U12="","",_xlfn.CONCAT("[",U12,"]")) | AN12: =IF(W12="","",_xlfn.CONCAT("[",W12,"]")) | AO12: =IF(Y12="","",_xlfn.CONCAT("[",Y12,"]")) | AP12: =IFERROR(IF(Z12<>"",_xlfn.XLOOKUP(Z12,[1]StuntDes!$B:$B,[1]StuntDes!$A:$A,""),""),"") | AQ12: =IFERROR(IF(AA12<>"",_xlfn.XLOOKUP(AA12,[1]StuntDes!$B:$B,[1]StuntDes!$A:$A,""),""),"")
A13: =C13*10+D13 -> 60223 | B13: 拳斗熊-星级3 | C13: 6022 | D13: 3 | E13: ="[["&C13+10000&",1]]" -> [[16022,1]] | G13: =_xlfn.TEXTJOIN("|",TRUE,AH13:AJ13) -> 10124|10178 | H13: =IF(R13="","",_xlfn.CONCAT("[",_xlfn.TEXTJOIN(",",TRUE,AL13:AO13),"]")) -> [[0.2],[0.07]] | I13: =_xlfn.TEXTJOIN("|",TRUE,AP13:AQ13) | J13: =IF(AB13="","",_xlfn.CONCAT("[",_xlfn.TEXTJOIN(",",TRUE,AE13:AG13),"]")) -> [[10303,0.1],[11055,0.2]] | K13: =_xlfn.XLOOKUP(C13,Pet!A:A,Pet!E:E) -> SSR-物理 | L13: 物理伤害提高 | M13: 0.1 | N13: 流血效果比例 | O13: 0.2 | R13: 物理伤害额外提高 | S13: 0.2 | T13: 物理伤害双倍伤害几率增加 | U13: 0.07 | AB13: =IFERROR(IF(L13<>"",_xlfn.XLOOKUP(L13,[1]AttributeName!$C:$C,[1]AttributeName!$B:$B,""),""),"") -> 10303 | AC13: =IFERROR(IF(N13<>"",_xlfn.XLOOKUP(N13,[1]AttributeName!$C:$C,[1]AttributeName!$B:$B,""),""),"") -> 11055 | AD13: =IFERROR(IF(P13<>"",_xlfn.XLOOKUP(P13,[1]AttributeName!$C:$C,[1]AttributeName!$B:$B,""),""),"") | AE13: =IF(AB13="","",_xlfn.CONCAT("[",AB13,",",M13,"]")) -> [10303,0.1] | AF13: =IF(AC13="","",_xlfn.CONCAT("[",AC13,",",O13,"]")) -> [11055,0.2] | AG13: =IF(AD13="","",_xlfn.CONCAT("[",AD13,",",Q13,"]")) | AH13: =IFERROR(IF(R13<>"",_xlfn.XLOOKUP(R13,[1]ModifierDes!$B:$B,[1]ModifierDes!$A:$A,""),""),"") -> 10124 | AI13: =IFERROR(IF(T13<>"",_xlfn.XLOOKUP(T13,[1]ModifierDes!$B:$B,[1]ModifierDes!$A:$A,""),""),"") -> 10178 | AJ13: =IFERROR(IF(V13<>"",_xlfn.XLOOKUP(V13,[1]ModifierDes!$B:$B,[1]ModifierDes!$A:$A,""),""),"") | AK13: =IFERROR(IF(X13<>"",_xlfn.XLOOKUP(X13,[1]ModifierDes!$B:$B,[1]ModifierDes!$A:$A,""),""),"") | AL13: =IF(S13="","",_xlfn.CONCAT("[",S13,"]")) -> [0.2] | AM13: =IF(U13="","",_xlfn.CONCAT("[",U13,"]")) -> [0.07] | AN13: =IF(W13="","",_xlfn.CONCAT("[",W13,"]")) | AO13: =IF(Y13="","",_xlfn.CONCAT("[",Y13,"]")) | AP13: =IFERROR(IF(Z13<>"",_xlfn.XLOOKUP(Z13,[1]StuntDes!$B:$B,[1]StuntDes!$A:$A,""),""),"") | AQ13: =IFERROR(IF(AA13<>"",_xlfn.XLOOKUP(AA13,[1]StuntDes!$B:$B,[1]StuntDes!$A:$A,""),""),"")
A14: =C14*10+D14 -> 60224 | B14: 拳斗熊-星级4 | C14: 6022 | D14: 4 | E14: ="[["&C14+10000&",1]]" -> [[16022,1]] | G14: =_xlfn.TEXTJOIN("|",TRUE,AH14:AJ14) -> 10124 | H14: =IF(R14="","",_xlfn.CONCAT("[",_xlfn.TEXTJOIN(",",TRUE,AL14:AO14),"]")) -> [[0.28]] | I14: =_xlfn.TEXTJOIN("|",TRUE,AP14:AQ14) | J14: =IF(AB14="","",_xlfn.CONCAT("[",_xlfn.TEXTJOIN(",",TRUE,AE14:AG14),"]")) -> [[10303,0.15],[11055,0.2]] | K14: =_xlfn.XLOOKUP(C14,Pet!A:A,Pet!E:E) -> SSR-物理 | L14: 物理伤害提高 | M14: 0.15 | N14: 流血效果比例 | O14: 0.2 | R14: 物理伤害额外提高 | S14: 0.28 | AB14: =IFERROR(IF(L14<>"",_xlfn.XLOOKUP(L14,[1]AttributeName!$C:$C,[1]AttributeName!$B:$B,""),""),"") -> 10303 | AC14: =IFERROR(IF(N14<>"",_xlfn.XLOOKUP(N14,[1]AttributeName!$C:$C,[1]AttributeName!$B:$B,""),""),"") -> 11055 | AD14: =IFERROR(IF(P14<>"",_xlfn.XLOOKUP(P14,[1]AttributeName!$C:$C,[1]AttributeName!$B:$B,""),""),"") | AE14: =IF(AB14="","",_xlfn.CONCAT("[",AB14,",",M14,"]")) -> [10303,0.15] | AF14: =IF(AC14="","",_xlfn.CONCAT("[",AC14,",",O14,"]")) -> [11055,0.2] | AG14: =IF(AD14="","",_xlfn.CONCAT("[",AD14,",",Q14,"]")) | AH14: =IFERROR(IF(R14<>"",_xlfn.XLOOKUP(R14,[1]ModifierDes!$B:$B,[1]ModifierDes!$A:$A,""),""),"") -> 10124 | AI14: =IFERROR(IF(T14<>"",_xlfn.XLOOKUP(T14,[1]ModifierDes!$B:$B,[1]ModifierDes!$A:$A,""),""),"") | AJ14: =IFERROR(IF(V14<>"",_xlfn.XLOOKUP(V14,[1]ModifierDes!$B:$B,[1]ModifierDes!$A:$A,""),""),"") | AK14: =IFERROR(IF(X14<>"",_xlfn.XLOOKUP(X14,[1]ModifierDes!$B:$B,[1]ModifierDes!$A:$A,""),""),"") | AL14: =IF(S14="","",_xlfn.CONCAT("[",S14,"]")) -> [0.28] | AM14: =IF(U14="","",_xlfn.CONCAT("[",U14,"]")) | AN14: =IF(W14="","",_xlfn.CONCAT("[",W14,"]")) | AO14: =IF(Y14="","",_xlfn.CONCAT("[",Y14,"]")) | AP14: =IFERROR(IF(Z14<>"",_xlfn.XLOOKUP(Z14,[1]StuntDes!$B:$B,[1]StuntDes!$A:$A,""),""),"") | AQ14: =IFERROR(IF(AA14<>"",_xlfn.XLOOKUP(AA14,[1]StuntDes!$B:$B,[1]StuntDes!$A:$A,""),""),"")
A15: =C15*10+D15 -> 60225 | B15: 拳斗熊-星级5 | C15: 6022 | D15: 5 | G15: =_xlfn.TEXTJOIN("|",TRUE,AH15:AJ15) -> 10124|10178 | H15: =IF(R15="","",_xlfn.CONCAT("[",_xlfn.TEXTJOIN(",",TRUE,AL15:AO15),"]")) -> [[0.28],[0.2]] | I15: =_xlfn.TEXTJOIN("|",TRUE,AP15:AQ15) | J15: =IF(AB15="","",_xlfn.CONCAT("[",_xlfn.TEXTJOIN(",",TRUE,AE15:AG15),"]")) -> [[10303,0.15],[11055,0.3]] | K15: =_xlfn.XLOOKUP(C15,Pet!A:A,Pet!E:E) -> SSR-物理 | L15: 物理伤害提高 | M15: 0.15 | N15: 流血效果比例 | O15: 0.3 | R15: 物理伤害额外提高 | S15: 0.28 | T15: 物理伤害双倍伤害几率增加 | U15: 0.2 | AB15: =IFERROR(IF(L15<>"",_xlfn.XLOOKUP(L15,[1]AttributeName!$C:$C,[1]AttributeName!$B:$B,""),""),"") -> 10303 | AC15: =IFERROR(IF(N15<>"",_xlfn.XLOOKUP(N15,[1]AttributeName!$C:$C,[1]AttributeName!$B:$B,""),""),"") -> 11055 | AD15: =IFERROR(IF(P15<>"",_xlfn.XLOOKUP(P15,[1]AttributeName!$C:$C,[1]AttributeName!$B:$B,""),""),"") | AE15: =IF(AB15="","",_xlfn.CONCAT("[",AB15,",",M15,"]")) -> [10303,0.15] | AF15: =IF(AC15="","",_xlfn.CONCAT("[",AC15,",",O15,"]")) -> [11055,0.3] | AG15: =IF(AD15="","",_xlfn.CONCAT("[",AD15,",",Q15,"]")) | AH15: =IFERROR(IF(R15<>"",_xlfn.XLOOKUP(R15,[1]ModifierDes!$B:$B,[1]ModifierDes!$A:$A,""),""),"") -> 10124 | AI15: =IFERROR(IF(T15<>"",_xlfn.XLOOKUP(T15,[1]ModifierDes!$B:$B,[1]ModifierDes!$A:$A,""),""),"") -> 10178 | AJ15: =IFERROR(IF(V15<>"",_xlfn.XLOOKUP(V15,[1]ModifierDes!$B:$B,[1]ModifierDes!$A:$A,""),""),"") | AK15: =IFERROR(IF(X15<>"",_xlfn.XLOOKUP(X15,[1]ModifierDes!$B:$B,[1]ModifierDes!$A:$A,""),""),"") | AL15: =IF(S15="","",_xlfn.CONCAT("[",S15,"]")) -> [0.28] | AM15: =IF(U15="","",_xlfn.CONCAT("[",U15,"]")) -> [0.2] | AN15: =IF(W15="","",_xlfn.CONCAT("[",W15,"]")) | AO15: =IF(Y15="","",_xlfn.CONCAT("[",Y15,"]")) | AP15: =IFERROR(IF(Z15<>"",_xlfn.XLOOKUP(Z15,[1]StuntDes!$B:$B,[1]StuntDes!$A:$A,""),""),"") | AQ15: =IFERROR(IF(AA15<>"",_xlfn.XLOOKUP(AA15,[1]StuntDes!$B:$B,[1]StuntDes!$A:$A,""),""),"")
A16: =C16*10+D16 -> 50300 | B16: 沙虫-星级0 | C16: 5030 | D16: 0 | E16: ="[["&C16+10000&",1]]" -> [[15030,1]] | G16: =_xlfn.TEXTJOIN("|",TRUE,AH16:AJ16) -> 10031|10050|10127 | H16: =IF(R16="","",_xlfn.CONCAT("[",_xlfn.TEXTJOIN(",",TRUE,AL16:AO16),"]")) -> [[0.1,0.2],[0.3],[0.5]] | I16: =_xlfn.TEXTJOIN("|",TRUE,AP16:AQ16) | J16: =IF(AB16="","",_xlfn.CONCAT("[",_xlfn.TEXTJOIN(",",TRUE,AE16:AG16),"]")) -> [[10306,0.05],[11010,0.1]] | K16: =_xlfn.XLOOKUP(C16,Pet!A:A,Pet!E:E) -> 无 | L16: 闪电伤害提高 | M16: 0.05 | N16: 感电效果比例 | O16: 0.1 | R16: 攻击速度提高 | S16: 0.1,0.2 | T16: 施法速度提高 | U16: 0.3 | V16: 闪电伤害额外提高 | W16: 0.5 | AB16: =IFERROR(IF(L16<>"",_xlfn.XLOOKUP(L16,[1]AttributeName!$C:$C,[1]AttributeName!$B:$B,""),""),"") -> 10306 | AC16: =IFERROR(IF(N16<>"",_xlfn.XLOOKUP(N16,[1]AttributeName!$C:$C,[1]AttributeName!$B:$B,""),""),"") -> 11010 | AD16: =IFERROR(IF(P16<>"",_xlfn.XLOOKUP(P16,[1]AttributeName!$C:$C,[1]AttributeName!$B:$B,""),""),"") | AE16: =IF(AB16="","",_xlfn.CONCAT("[",AB16,",",M16,"]")) -> [10306,0.05] | AF16: =IF(AC16="","",_xlfn.CONCAT("[",AC16,",",O16,"]")) -> [11010,0.1] | AG16: =IF(AD16="","",_xlfn.CONCAT("[",AD16,",",Q16,"]")) | AH16: =IFERROR(IF(R16<>"",_xlfn.XLOOKUP(R16,[1]ModifierDes!$B:$B,[1]ModifierDes!$A:$A,""),""),"") -> 10031 | AI16: =IFERROR(IF(T16<>"",_xlfn.XLOOKUP(T16,[1]ModifierDes!$B:$B,[1]ModifierDes!$A:$A,""),""),"") -> 10050 | AJ16: =IFERROR(IF(V16<>"",_xlfn.XLOOKUP(V16,[1]ModifierDes!$B:$B,[1]ModifierDes!$A:$A,""),""),"") -> 10127 | AK16: =IFERROR(IF(X16<>"",_xlfn.XLOOKUP(X16,[1]ModifierDes!$B:$B,[1]ModifierDes!$A:$A,""),""),"") | AL16: =IF(S16="","",_xlfn.CONCAT("[",S16,"]")) -> [0.1,0.2] | AM16: =IF(U16="","",_xlfn.CONCAT("[",U16,"]")) -> [0.3] | AN16: =IF(W16="","",_xlfn.CONCAT("[",W16,"]")) -> [0.5] | AO16: =IF(Y16="","",_xlfn.CONCAT("[",Y16,"]")) | AP16: =IFERROR(IF(Z16<>"",_xlfn.XLOOKUP(Z16,[1]StuntDes!$B:$B,[1]StuntDes!$A:$A,""),""),"") | AQ16: =IFERROR(IF(AA16<>"",_xlfn.XLOOKUP(AA16,[1]StuntDes!$B:$B,[1]StuntDes!$A:$A,""),""),"")
A17: =C17*10+D17 -> 50301 | B17: 沙虫-星级1 | C17: 5030 | D17: 1 | E17: ="[["&C17+10000&",1]]" -> [[15030,1]] | G17: =_xlfn.TEXTJOIN("|",TRUE,AH17:AJ17) -> 10031|10050|10127 | H17: =IF(R17="","",_xlfn.CONCAT("[",_xlfn.TEXTJOIN(",",TRUE,AL17:AO17),"]")) -> [[0.1,0.2],[0.3],[0.5]] | I17: =_xlfn.TEXTJOIN("|",TRUE,AP17:AQ17) -> 2110000010 | J17: =IF(AB17="","",_xlfn.CONCAT("[",_xlfn.TEXTJOIN(",",TRUE,AE17:AG17),"]")) -> [[10306,0.05],[11010,0.1]] | K17: =_xlfn.XLOOKUP(C17,Pet!A:A,Pet!E:E) -> 无 | L17: 闪电伤害提高 | M17: 0.05 | N17: 感电效果比例 | O17: 0.1 | R17: 攻击速度提高 | S17: 0.1,0.2 | T17: 施法速度提高 | U17: 0.3 | V17: 闪电伤害额外提高 | W17: 0.5 | Z17: 闪电之捷 | AB17: =IFERROR(IF(L17<>"",_xlfn.XLOOKUP(L17,[1]AttributeName!$C:$C,[1]AttributeName!$B:$B,""),""),"") -> 10306 | AC17: =IFERROR(IF(N17<>"",_xlfn.XLOOKUP(N17,[1]AttributeName!$C:$C,[1]AttributeName!$B:$B,""),""),"") -> 11010 | AD17: =IFERROR(IF(P17<>"",_xlfn.XLOOKUP(P17,[1]AttributeName!$C:$C,[1]AttributeName!$B:$B,""),""),"") | AE17: =IF(AB17="","",_xlfn.CONCAT("[",AB17,",",M17,"]")) -> [10306,0.05] | AF17: =IF(AC17="","",_xlfn.CONCAT("[",AC17,",",O17,"]")) -> [11010,0.1] | AG17: =IF(AD17="","",_xlfn.CONCAT("[",AD17,",",Q17,"]")) | AH17: =IFERROR(IF(R17<>"",_xlfn.XLOOKUP(R17,[1]ModifierDes!$B:$B,[1]ModifierDes!$A:$A,""),""),"") -> 10031 | AI17: =IFERROR(IF(T17<>"",_xlfn.XLOOKUP(T17,[1]ModifierDes!$B:$B,[1]ModifierDes!$A:$A,""),""),"") -> 10050 | AJ17: =IFERROR(IF(V17<>"",_xlfn.XLOOKUP(V17,[1]ModifierDes!$B:$B,[1]ModifierDes!$A:$A,""),""),"") -> 10127 | AK17: =IFERROR(IF(X17<>"",_xlfn.XLOOKUP(X17,[1]ModifierDes!$B:$B,[1]ModifierDes!$A:$A,""),""),"") | AL17: =IF(S17="","",_xlfn.CONCAT("[",S17,"]")) -> [0.1,0.2] | AM17: =IF(U17="","",_xlfn.CONCAT("[",U17,"]")) -> [0.3] | AN17: =IF(W17="","",_xlfn.CONCAT("[",W17,"]")) -> [0.5] | AO17: =IF(Y17="","",_xlfn.CONCAT("[",Y17,"]")) | AP17: =IFERROR(IF(Z17<>"",_xlfn.XLOOKUP(Z17,[1]StuntDes!$B:$B,[1]StuntDes!$A:$A,""),""),"") -> 2110000010 | AQ17: =IFERROR(IF(AA17<>"",_xlfn.XLOOKUP(AA17,[1]StuntDes!$B:$B,[1]StuntDes!$A:$A,""),""),"")
A18: =C18*10+D18 -> 50302 | B18: 沙虫-星级2 | C18: 5030 | D18: 2 | E18: ="[["&C18+10000&",1]]" -> [[15030,1]] | G18: =_xlfn.TEXTJOIN("|",TRUE,AH18:AJ18) -> 10031|10050|10127 | H18: =IF(R18="","",_xlfn.CONCAT("[",_xlfn.TEXTJOIN(",",TRUE,AL18:AO18),"]")) -> [[0.1,0.2],[0.3],[0.5]] | I18: =_xlfn.TEXTJOIN("|",TRUE,AP18:AQ18) -> 2110000010 | J18: =IF(AB18="","",_xlfn.CONCAT("[",_xlfn.TEXTJOIN(",",TRUE,AE18:AG18),"]")) -> [[10306,0.05],[11010,0.1]] | K18: =_xlfn.XLOOKUP(C18,Pet!A:A,Pet!E:E) -> 无 | L18: 闪电伤害提高 | M18: 0.05 | N18: 感电效果比例 | O18: 0.1 | R18: 攻击速度提高 | S18: 0.1,0.2 | T18: 施法速度提高 | U18: 0.3 | V18: 闪电伤害额外提高 | W18: 0.5 | Z18: 闪电之捷 | AB18: =IFERROR(IF(L18<>"",_xlfn.XLOOKUP(L18,[1]AttributeName!$C:$C,[1]AttributeName!$B:$B,""),""),"") -> 10306 | AC18: =IFERROR(IF(N18<>"",_xlfn.XLOOKUP(N18,[1]AttributeName!$C:$C,[1]AttributeName!$B:$B,""),""),"") -> 11010 | AD18: =IFERROR(IF(P18<>"",_xlfn.XLOOKUP(P18,[1]AttributeName!$C:$C,[1]AttributeName!$B:$B,""),""),"") | AE18: =IF(AB18="","",_xlfn.CONCAT("[",AB18,",",M18,"]")) -> [10306,0.05] | AF18: =IF(AC18="","",_xlfn.CONCAT("[",AC18,",",O18,"]")) -> [11010,0.1] | AG18: =IF(AD18="","",_xlfn.CONCAT("[",AD18,",",Q18,"]")) | AH18: =IFERROR(IF(R18<>"",_xlfn.XLOOKUP(R18,[1]ModifierDes!$B:$B,[1]ModifierDes!$A:$A,""),""),"") -> 10031 | AI18: =IFERROR(IF(T18<>"",_xlfn.XLOOKUP(T18,[1]ModifierDes!$B:$B,[1]ModifierDes!$A:$A,""),""),"") -> 10050 | AJ18: =IFERROR(IF(V18<>"",_xlfn.XLOOKUP(V18,[1]ModifierDes!$B:$B,[1]ModifierDes!$A:$A,""),""),"") -> 10127 | AK18: =IFERROR(IF(X18<>"",_xlfn.XLOOKUP(X18,[1]ModifierDes!$B:$B,[1]ModifierDes!$A:$A,""),""),"") | AL18: =IF(S18="","",_xlfn.CONCAT("[",S18,"]")) -> [0.1,0.2] | AM18: =IF(U18="","",_xlfn.CONCAT("[",U18,"]")) -> [0.3] | AN18: =IF(W18="","",_xlfn.CONCAT("[",W18,"]")) -> [0.5] | AO18: =IF(Y18="","",_xlfn.CONCAT("[",Y18,"]")) | AP18: =IFERROR(IF(Z18<>"",_xlfn.XLOOKUP(Z18,[1]StuntDes!$B:$B,[1]StuntDes!$A:$A,""),""),"") -> 2110000010 | AQ18: =IFERROR(IF(AA18<>"",_xlfn.XLOOKUP(AA18,[1]StuntDes!$B:$B,[1]StuntDes!$A:$A,""),""),"")
A19: =C19*10+D19 -> 50303 | B19: 沙虫-星级3 | C19: 5030 | D19: 3 | E19: ="[["&C19+10000&",1]]" -> [[15030,1]] | G19: =_xlfn.TEXTJOIN("|",TRUE,AH19:AJ19) -> 10031|10050|10127 | H19: =IF(R19="","",_xlfn.CONCAT("[",_xlfn.TEXTJOIN(",",TRUE,AL19:AO19),"]")) -> [[0.1,0.2],[0.3],[0.5]] | I19: =_xlfn.TEXTJOIN("|",TRUE,AP19:AQ19) -> 2110000010 | J19: =IF(AB19="","",_xlfn.CONCAT("[",_xlfn.TEXTJOIN(",",TRUE,AE19:AG19),"]")) -> [[10306,0.05],[11010,0.1]] | K19: =_xlfn.XLOOKUP(C19,Pet!A:A,Pet!E:E) -> 无 | L19: 闪电伤害提高 | M19: 0.05 | N19: 感电效果比例 | O19: 0.1 | R19: 攻击速度提高 | S19: 0.1,0.2 | T19: 施法速度提高 | U19: 0.3 | V19: 闪电伤害额外提高 | W19: 0.5 | Z19: 闪电之捷 | AB19: =IFERROR(IF(L19<>"",_xlfn.XLOOKUP(L19,[1]AttributeName!$C:$C,[1]AttributeName!$B:$B,""),""),"") -> 10306 | AC19: =IFERROR(IF(N19<>"",_xlfn.XLOOKUP(N19,[1]AttributeName!$C:$C,[1]AttributeName!$B:$B,""),""),"") -> 11010 | AD19: =IFERROR(IF(P19<>"",_xlfn.XLOOKUP(P19,[1]AttributeName!$C:$C,[1]AttributeName!$B:$B,""),""),"") | AE19: =IF(AB19="","",_xlfn.CONCAT("[",AB19,",",M19,"]")) -> [10306,0.05] | AF19: =IF(AC19="","",_xlfn.CONCAT("[",AC19,",",O19,"]")) -> [11010,0.1] | AG19: =IF(AD19="","",_xlfn.CONCAT("[",AD19,",",Q19,"]")) | AH19: =IFERROR(IF(R19<>"",_xlfn.XLOOKUP(R19,[1]ModifierDes!$B:$B,[1]ModifierDes!$A:$A,""),""),"") -> 10031 | AI19: =IFERROR(IF(T19<>"",_xlfn.XLOOKUP(T19,[1]ModifierDes!$B:$B,[1]ModifierDes!$A:$A,""),""),"") -> 10050 | AJ19: =IFERROR(IF(V19<>"",_xlfn.XLOOKUP(V19,[1]ModifierDes!$B:$B,[1]ModifierDes!$A:$A,""),""),"") -> 10127 | AK19: =IFERROR(IF(X19<>"",_xlfn.XLOOKUP(X19,[1]ModifierDes!$B:$B,[1]ModifierDes!$A:$A,""),""),"") | AL19: =IF(S19="","",_xlfn.CONCAT("[",S19,"]")) -> [0.1,0.2] | AM19: =IF(U19="","",_xlfn.CONCAT("[",U19,"]")) -> [0.3] | AN19: =IF(W19="","",_xlfn.CONCAT("[",W19,"]")) -> [0.5] | AO19: =IF(Y19="","",_xlfn.CONCAT("[",Y19,"]")) | AP19: =IFERROR(IF(Z19<>"",_xlfn.XLOOKUP(Z19,[1]StuntDes!$B:$B,[1]StuntDes!$A:$A,""),""),"") -> 2110000010 | AQ19: =IFERROR(IF(AA19<>"",_xlfn.XLOOKUP(AA19,[1]StuntDes!$B:$B,[1]StuntDes!$A:$A,""),""),"")
A20: =C20*10+D20 -> 50304 | B20: 沙虫-星级4 | C20: 5030 | D20: 4 | E20: ="[["&C20+10000&",1]]" -> [[15030,1]] | G20: =_xlfn.TEXTJOIN("|",TRUE,AH20:AJ20) -> 10031|10050|10127 | H20: =IF(R20="","",_xlfn.CONCAT("[",_xlfn.TEXTJOIN(",",TRUE,AL20:AO20),"]")) -> [[0.1,0.2],[0.3],[0.5]] | I20: =_xlfn.TEXTJOIN("|",TRUE,AP20:AQ20) -> 2110000010|2110000020 | J20: =IF(AB20="","",_xlfn.CONCAT("[",_xlfn.TEXTJOIN(",",TRUE,AE20:AG20),"]")) -> [[10306,0.05],[11010,0.1]] | K20: =_xlfn.XLOOKUP(C20,Pet!A:A,Pet!E:E) -> 无 | L20: 闪电伤害提高 | M20: 0.05 | N20: 感电效果比例 | O20: 0.1 | R20: 攻击速度提高 | S20: 0.1,0.2 | T20: 施法速度提高 | U20: 0.3 | V20: 闪电伤害额外提高 | W20: 0.5 | Z20: 闪电之捷 | AA20: 灰烬之捷 | AB20: =IFERROR(IF(L20<>"",_xlfn.XLOOKUP(L20,[1]AttributeName!$C:$C,[1]AttributeName!$B:$B,""),""),"") -> 10306 | AC20: =IFERROR(IF(N20<>"",_xlfn.XLOOKUP(N20,[1]AttributeName!$C:$C,[1]AttributeName!$B:$B,""),""),"") -> 11010 | AD20: =IFERROR(IF(P20<>"",_xlfn.XLOOKUP(P20,[1]AttributeName!$C:$C,[1]AttributeName!$B:$B,""),""),"") | AE20: =IF(AB20="","",_xlfn.CONCAT("[",AB20,",",M20,"]")) -> [10306,0.05] | AF20: =IF(AC20="","",_xlfn.CONCAT("[",AC20,",",O20,"]")) -> [11010,0.1] | AG20: =IF(AD20="","",_xlfn.CONCAT("[",AD20,",",Q20,"]")) | AH20: =IFERROR(IF(R20<>"",_xlfn.XLOOKUP(R20,[1]ModifierDes!$B:$B,[1]ModifierDes!$A:$A,""),""),"") -> 10031 | AI20: =IFERROR(IF(T20<>"",_xlfn.XLOOKUP(T20,[1]ModifierDes!$B:$B,[1]ModifierDes!$A:$A,""),""),"") -> 10050 | AJ20: =IFERROR(IF(V20<>"",_xlfn.XLOOKUP(V20,[1]ModifierDes!$B:$B,[1]ModifierDes!$A:$A,""),""),"") -> 10127 | AK20: =IFERROR(IF(X20<>"",_xlfn.XLOOKUP(X20,[1]ModifierDes!$B:$B,[1]ModifierDes!$A:$A,""),""),"") | AL20: =IF(S20="","",_xlfn.CONCAT("[",S20,"]")) -> [0.1,0.2] | AM20: =IF(U20="","",_xlfn.CONCAT("[",U20,"]")) -> [0.3] | AN20: =IF(W20="","",_xlfn.CONCAT("[",W20,"]")) -> [0.5] | AO20: =IF(Y20="","",_xlfn.CONCAT("[",Y20,"]")) | AP20: =IFERROR(IF(Z20<>"",_xlfn.XLOOKUP(Z20,[1]StuntDes!$B:$B,[1]StuntDes!$A:$A,""),""),"") -> 2110000010 | AQ20: =IFERROR(IF(AA20<>"",_xlfn.XLOOKUP(AA20,[1]StuntDes!$B:$B,[1]StuntDes!$A:$A,""),""),"") -> 2110000020
A21: =C21*10+D21 -> 50305 | B21: 沙虫-星级5 | C21: 5030 | D21: 5 | G21: =_xlfn.TEXTJOIN("|",TRUE,AH21:AJ21) -> 10031|10050|10127 | H21: =IF(R21="","",_xlfn.CONCAT("[",_xlfn.TEXTJOIN(",",TRUE,AL21:AO21),"]")) -> [[0.1,0.2],[0.3],[0.5]] | I21: =_xlfn.TEXTJOIN("|",TRUE,AP21:AQ21) -> 2110000010|2110000020 | J21: =IF(AB21="","",_xlfn.CONCAT("[",_xlfn.TEXTJOIN(",",TRUE,AE21:AG21),"]")) -> [[10306,0.05],[11010,0.1]] | K21: =_xlfn.XLOOKUP(C21,Pet!A:A,Pet!E:E) -> 无 | L21: 闪电伤害提高 | M21: 0.05 | N21: 感电效果比例 | O21: 0.1 | R21: 攻击速度提高 | S21: 0.1,0.2 | T21: 施法速度提高 | U21: 0.3 | V21: 闪电伤害额外提高 | W21: 0.5 | Z21: 闪电之捷 | AA21: 灰烬之捷 | AB21: =IFERROR(IF(L21<>"",_xlfn.XLOOKUP(L21,[1]AttributeName!$C:$C,[1]AttributeName!$B:$B,""),""),"") -> 10306 | AC21: =IFERROR(IF(N21<>"",_xlfn.XLOOKUP(N21,[1]AttributeName!$C:$C,[1]AttributeName!$B:$B,""),""),"") -> 11010 | AD21: =IFERROR(IF(P21<>"",_xlfn.XLOOKUP(P21,[1]AttributeName!$C:$C,[1]AttributeName!$B:$B,""),""),"") | AE21: =IF(AB21="","",_xlfn.CONCAT("[",AB21,",",M21,"]")) -> [10306,0.05] | AF21: =IF(AC21="","",_xlfn.CONCAT("[",AC21,",",O21,"]")) -> [11010,0.1] | AG21: =IF(AD21="","",_xlfn.CONCAT("[",AD21,",",Q21,"]")) | AH21: =IFERROR(IF(R21<>"",_xlfn.XLOOKUP(R21,[1]ModifierDes!$B:$B,[1]ModifierDes!$A:$A,""),""),"") -> 10031 | AI21: =IFERROR(IF(T21<>"",_xlfn.XLOOKUP(T21,[1]ModifierDes!$B:$B,[1]ModifierDes!$A:$A,""),""),"") -> 10050 | AJ21: =IFERROR(IF(V21<>"",_xlfn.XLOOKUP(V21,[1]ModifierDes!$B:$B,[1]ModifierDes!$A:$A,""),""),"") -> 10127 | AK21: =IFERROR(IF(X21<>"",_xlfn.XLOOKUP(X21,[1]ModifierDes!$B:$B,[1]ModifierDes!$A:$A,""),""),"") | AL21: =IF(S21="","",_xlfn.CONCAT("[",S21,"]")) -> [0.1,0.2] | AM21: =IF(U21="","",_xlfn.CONCAT("[",U21,"]")) -> [0.3] | AN21: =IF(W21="","",_xlfn.CONCAT("[",W21,"]")) -> [0.5] | AO21: =IF(Y21="","",_xlfn.CONCAT("[",Y21,"]")) | AP21: =IFERROR(IF(Z21<>"",_xlfn.XLOOKUP(Z21,[1]StuntDes!$B:$B,[1]StuntDes!$A:$A,""),""),"") -> 2110000010 | AQ21: =IFERROR(IF(AA21<>"",_xlfn.XLOOKUP(AA21,[1]StuntDes!$B:$B,[1]StuntDes!$A:$A,""),""),"") -> 2110000020
A22: =C22*10+D22 -> 50400 | B22: 小炎龙-星级0 | C22: 5040 | D22: 0 | E22: ="[["&C22+10000&",1]]" -> [[15040,1]] | G22: =_xlfn.TEXTJOIN("|",TRUE,AH22:AJ22) | H22: =IF(R22="","",_xlfn.CONCAT("[",_xlfn.TEXTJOIN(",",TRUE,AL22:AO22),"]")) | I22: =_xlfn.TEXTJOIN("|",TRUE,AP22:AQ22) | J22: =IF(AB22="","",_xlfn.CONCAT("[",_xlfn.TEXTJOIN(",",TRUE,AE22:AG22),"]")) -> [[10304,0.08],[11007,0.04]] | K22: =_xlfn.XLOOKUP(C22,Pet!A:A,Pet!E:E) -> R-火焰 | L22: 火焰伤害提高 | M22: 0.08 | N22: 点燃效果比例 | O22: 0.04 | AB22: =IFERROR(IF(L22<>"",_xlfn.XLOOKUP(L22,[1]AttributeName!$C:$C,[1]AttributeName!$B:$B,""),""),"") -> 10304 | AC22: =IFERROR(IF(N22<>"",_xlfn.XLOOKUP(N22,[1]AttributeName!$C:$C,[1]AttributeName!$B:$B,""),""),"") -> 11007 | AD22: =IFERROR(IF(P22<>"",_xlfn.XLOOKUP(P22,[1]AttributeName!$C:$C,[1]AttributeName!$B:$B,""),""),"") | AE22: =IF(AB22="","",_xlfn.CONCAT("[",AB22,",",M22,"]")) -> [10304,0.08] | AF22: =IF(AC22="","",_xlfn.CONCAT("[",AC22,",",O22,"]")) -> [11007,0.04] | AG22: =IF(AD22="","",_xlfn.CONCAT("[",AD22,",",Q22,"]")) | AH22: =IFERROR(IF(R22<>"",_xlfn.XLOOKUP(R22,[1]ModifierDes!$B:$B,[1]ModifierDes!$A:$A,""),""),"") | AI22: =IFERROR(IF(T22<>"",_xlfn.XLOOKUP(T22,[1]ModifierDes!$B:$B,[1]ModifierDes!$A:$A,""),""),"") | AJ22: =IFERROR(IF(V22<>"",_xlfn.XLOOKUP(V22,[1]ModifierDes!$B:$B,[1]ModifierDes!$A:$A,""),""),"") | AK22: =IFERROR(IF(X22<>"",_xlfn.XLOOKUP(X22,[1]ModifierDes!$B:$B,[1]ModifierDes!$A:$A,""),""),"") | AL22: =IF(S22="","",_xlfn.CONCAT("[",S22,"]")) | AM22: =IF(U22="","",_xlfn.CONCAT("[",U22,"]")) | AN22: =IF(W22="","",_xlfn.CONCAT("[",W22,"]")) | AO22: =IF(Y22="","",_xlfn.CONCAT("[",Y22,"]")) | AP22: =IFERROR(IF(Z22<>"",_xlfn.XLOOKUP(Z22,[1]StuntDes!$B:$B,[1]StuntDes!$A:$A,""),""),"") | AQ22: =IFERROR(IF(AA22<>"",_xlfn.XLOOKUP(AA22,[1]StuntDes!$B:$B,[1]StuntDes!$A:$A,""),""),"")
A23: =C23*10+D23 -> 50401 | B23: 小炎龙-星级1 | C23: 5040 | D23: 1 | E23: ="[["&C23+10000&",1]]" -> [[15040,1]] | G23: =_xlfn.TEXTJOIN("|",TRUE,AH23:AJ23) | H23: =IF(R23="","",_xlfn.CONCAT("[",_xlfn.TEXTJOIN(",",TRUE,AL23:AO23),"]")) | I23: =_xlfn.TEXTJOIN("|",TRUE,AP23:AQ23) | J23: =IF(AB23="","",_xlfn.CONCAT("[",_xlfn.TEXTJOIN(",",TRUE,AE23:AG23),"]")) -> [[10304,0.13],[11007,0.04]] | K23: =_xlfn.XLOOKUP(C23,Pet!A:A,Pet!E:E) -> R-火焰 | L23: 火焰伤害提高 | M23: 0.13 | N23: 点燃效果比例 | O23: 0.04 | AB23: =IFERROR(IF(L23<>"",_xlfn.XLOOKUP(L23,[1]AttributeName!$C:$C,[1]AttributeName!$B:$B,""),""),"") -> 10304 | AC23: =IFERROR(IF(N23<>"",_xlfn.XLOOKUP(N23,[1]AttributeName!$C:$C,[1]AttributeName!$B:$B,""),""),"") -> 11007 | AD23: =IFERROR(IF(P23<>"",_xlfn.XLOOKUP(P23,[1]AttributeName!$C:$C,[1]AttributeName!$B:$B,""),""),"") | AE23: =IF(AB23="","",_xlfn.CONCAT("[",AB23,",",M23,"]")) -> [10304,0.13] | AF23: =IF(AC23="","",_xlfn.CONCAT("[",AC23,",",O23,"]")) -> [11007,0.04] | AG23: =IF(AD23="","",_xlfn.CONCAT("[",AD23,",",Q23,"]")) | AH23: =IFERROR(IF(R23<>"",_xlfn.XLOOKUP(R23,[1]ModifierDes!$B:$B,[1]ModifierDes!$A:$A,""),""),"") | AI23: =IFERROR(IF(T23<>"",_xlfn.XLOOKUP(T23,[1]ModifierDes!$B:$B,[1]ModifierDes!$A:$A,""),""),"") | AJ23: =IFERROR(IF(V23<>"",_xlfn.XLOOKUP(V23,[1]ModifierDes!$B:$B,[1]ModifierDes!$A:$A,""),""),"") | AK23: =IFERROR(IF(X23<>"",_xlfn.XLOOKUP(X23,[1]ModifierDes!$B:$B,[1]ModifierDes!$A:$A,""),""),"") | AL23: =IF(S23="","",_xlfn.CONCAT("[",S23,"]")) | AM23: =IF(U23="","",_xlfn.CONCAT("[",U23,"]")) | AN23: =IF(W23="","",_xlfn.CONCAT("[",W23,"]")) | AO23: =IF(Y23="","",_xlfn.CONCAT("[",Y23,"]")) | AP23: =IFERROR(IF(Z23<>"",_xlfn.XLOOKUP(Z23,[1]StuntDes!$B:$B,[1]StuntDes!$A:$A,""),""),"") | AQ23: =IFERROR(IF(AA23<>"",_xlfn.XLOOKUP(AA23,[1]StuntDes!$B:$B,[1]StuntDes!$A:$A,""),""),"")
A24: =C24*10+D24 -> 50402 | B24: 小炎龙-星级2 | C24: 5040 | D24: 2 | E24: ="[["&C24+10000&",1]]" -> [[15040,1]] | G24: =_xlfn.TEXTJOIN("|",TRUE,AH24:AJ24) | H24: =IF(R24="","",_xlfn.CONCAT("[",_xlfn.TEXTJOIN(",",TRUE,AL24:AO24),"]")) | I24: =_xlfn.TEXTJOIN("|",TRUE,AP24:AQ24) | J24: =IF(AB24="","",_xlfn.CONCAT("[",_xlfn.TEXTJOIN(",",TRUE,AE24:AG24),"]")) -> [[10304,0.13],[11007,0.14]] | K24: =_xlfn.XLOOKUP(C24,Pet!A:A,Pet!E:E) -> R-火焰 | L24: 火焰伤害提高 | M24: 0.13 | N24: 点燃效果比例 | O24: 0.14 | AB24: =IFERROR(IF(L24<>"",_xlfn.XLOOKUP(L24,[1]AttributeName!$C:$C,[1]AttributeName!$B:$B,""),""),"") -> 10304 | AC24: =IFERROR(IF(N24<>"",_xlfn.XLOOKUP(N24,[1]AttributeName!$C:$C,[1]AttributeName!$B:$B,""),""),"") -> 11007 | AD24: =IFERROR(IF(P24<>"",_xlfn.XLOOKUP(P24,[1]AttributeName!$C:$C,[1]AttributeName!$B:$B,""),""),"") | AE24: =IF(AB24="","",_xlfn.CONCAT("[",AB24,",",M24,"]")) -> [10304,0.13] | AF24: =IF(AC24="","",_xlfn.CONCAT("[",AC24,",",O24,"]")) -> [11007,0.14] | AG24: =IF(AD24="","",_xlfn.CONCAT("[",AD24,",",Q24,"]")) | AH24: =IFERROR(IF(R24<>"",_xlfn.XLOOKUP(R24,[1]ModifierDes!$B:$B,[1]ModifierDes!$A:$A,""),""),"") | AI24: =IFERROR(IF(T24<>"",_xlfn.XLOOKUP(T24,[1]ModifierDes!$B:$B,[1]ModifierDes!$A:$A,""),""),"") | AJ24: =IFERROR(IF(V24<>"",_xlfn.XLOOKUP(V24,[1]ModifierDes!$B:$B,[1]ModifierDes!$A:$A,""),""),"") | AK24: =IFERROR(IF(X24<>"",_xlfn.XLOOKUP(X24,[1]ModifierDes!$B:$B,[1]ModifierDes!$A:$A,""),""),"") | AL24: =IF(S24="","",_xlfn.CONCAT("[",S24,"]")) | AM24: =IF(U24="","",_xlfn.CONCAT("[",U24,"]")) | AN24: =IF(W24="","",_xlfn.CONCAT("[",W24,"]")) | AO24: =IF(Y24="","",_xlfn.CONCAT("[",Y24,"]")) | AP24: =IFERROR(IF(Z24<>"",_xlfn.XLOOKUP(Z24,[1]StuntDes!$B:$B,[1]StuntDes!$A:$A,""),""),"") | AQ24: =IFERROR(IF(AA24<>"",_xlfn.XLOOKUP(AA24,[1]StuntDes!$B:$B,[1]StuntDes!$A:$A,""),""),"")
A25: =C25*10+D25 -> 50403 | B25: 小炎龙-星级3 | C25: 5040 | D25: 3 | E25: ="[["&C25+10000&",1]]" -> [[15040,1]] | G25: =_xlfn.TEXTJOIN("|",TRUE,AH25:AJ25) | H25: =IF(R25="","",_xlfn.CONCAT("[",_xlfn.TEXTJOIN(",",TRUE,AL25:AO25),"]")) | I25: =_xlfn.TEXTJOIN("|",TRUE,AP25:AQ25) | J25: =IF(AB25="","",_xlfn.CONCAT("[",_xlfn.TEXTJOIN(",",TRUE,AE25:AG25),"]")) -> [[10304,0.13],[11007,0.14],[10300,0.1]] | K25: =_xlfn.XLOOKUP(C25,Pet!A:A,Pet!E:E) -> R-火焰 | L25: 火焰伤害提高 | M25: 0.13 | N25: 点燃效果比例 | O25: 0.14 | P25: 全局伤害提高 | Q25: 0.1 | AB25: =IFERROR(IF(L25<>"",_xlfn.XLOOKUP(L25,[1]AttributeName!$C:$C,[1]AttributeName!$B:$B,""),""),"") -> 10304 | AC25: =IFERROR(IF(N25<>"",_xlfn.XLOOKUP(N25,[1]AttributeName!$C:$C,[1]AttributeName!$B:$B,""),""),"") -> 11007 | AD25: =IFERROR(IF(P25<>"",_xlfn.XLOOKUP(P25,[1]AttributeName!$C:$C,[1]AttributeName!$B:$B,""),""),"") -> 10300 | AE25: =IF(AB25="","",_xlfn.CONCAT("[",AB25,",",M25,"]")) -> [10304,0.13] | AF25: =IF(AC25="","",_xlfn.CONCAT("[",AC25,",",O25,"]")) -> [11007,0.14] | AG25: =IF(AD25="","",_xlfn.CONCAT("[",AD25,",",Q25,"]")) -> [10300,0.1] | AH25: =IFERROR(IF(R25<>"",_xlfn.XLOOKUP(R25,[1]ModifierDes!$B:$B,[1]ModifierDes!$A:$A,""),""),"") | AI25: =IFERROR(IF(T25<>"",_xlfn.XLOOKUP(T25,[1]ModifierDes!$B:$B,[1]ModifierDes!$A:$A,""),""),"") | AJ25: =IFERROR(IF(V25<>"",_xlfn.XLOOKUP(V25,[1]ModifierDes!$B:$B,[1]ModifierDes!$A:$A,""),""),"") | AK25: =IFERROR(IF(X25<>"",_xlfn.XLOOKUP(X25,[1]ModifierDes!$B:$B,[1]ModifierDes!$A:$A,""),""),"") | AL25: =IF(S25="","",_xlfn.CONCAT("[",S25,"]")) | AM25: =IF(U25="","",_xlfn.CONCAT("[",U25,"]")) | AN25: =IF(W25="","",_xlfn.CONCAT("[",W25,"]")) | AO25: =IF(Y25="","",_xlfn.CONCAT("[",Y25,"]")) | AP25: =IFERROR(IF(Z25<>"",_xlfn.XLOOKUP(Z25,[1]StuntDes!$B:$B,[1]StuntDes!$A:$A,""),""),"") | AQ25: =IFERROR(IF(AA25<>"",_xlfn.XLOOKUP(AA25,[1]StuntDes!$B:$B,[1]StuntDes!$A:$A,""),""),"")
A26: =C26*10+D26 -> 50404 | B26: 小炎龙-星级4 | C26: 5040 | D26: 4 | E26: ="[["&C26+10000&",1]]" -> [[15040,1]] | G26: =_xlfn.TEXTJOIN("|",TRUE,AH26:AJ26) | H26: =IF(R26="","",_xlfn.CONCAT("[",_xlfn.TEXTJOIN(",",TRUE,AL26:AO26),"]")) | I26: =_xlfn.TEXTJOIN("|",TRUE,AP26:AQ26) | J26: =IF(AB26="","",_xlfn.CONCAT("[",_xlfn.TEXTJOIN(",",TRUE,AE26:AG26),"]")) -> [[10304,0.22],[11007,0.14],[10300,0.1]] | K26: =_xlfn.XLOOKUP(C26,Pet!A:A,Pet!E:E) -> R-火焰 | L26: 火焰伤害提高 | M26: 0.22 | N26: 点燃效果比例 | O26: 0.14 | P26: 全局伤害提高 | Q26: 0.1 | AB26: =IFERROR(IF(L26<>"",_xlfn.XLOOKUP(L26,[1]AttributeName!$C:$C,[1]AttributeName!$B:$B,""),""),"") -> 10304 | AC26: =IFERROR(IF(N26<>"",_xlfn.XLOOKUP(N26,[1]AttributeName!$C:$C,[1]AttributeName!$B:$B,""),""),"") -> 11007 | AD26: =IFERROR(IF(P26<>"",_xlfn.XLOOKUP(P26,[1]AttributeName!$C:$C,[1]AttributeName!$B:$B,""),""),"") -> 10300 | AE26: =IF(AB26="","",_xlfn.CONCAT("[",AB26,",",M26,"]")) -> [10304,0.22] | AF26: =IF(AC26="","",_xlfn.CONCAT("[",AC26,",",O26,"]")) -> [11007,0.14] | AG26: =IF(AD26="","",_xlfn.CONCAT("[",AD26,",",Q26,"]")) -> [10300,0.1] | AH26: =IFERROR(IF(R26<>"",_xlfn.XLOOKUP(R26,[1]ModifierDes!$B:$B,[1]ModifierDes!$A:$A,""),""),"") | AI26: =IFERROR(IF(T26<>"",_xlfn.XLOOKUP(T26,[1]ModifierDes!$B:$B,[1]ModifierDes!$A:$A,""),""),"") | AJ26: =IFERROR(IF(V26<>"",_xlfn.XLOOKUP(V26,[1]ModifierDes!$B:$B,[1]ModifierDes!$A:$A,""),""),"") | AK26: =IFERROR(IF(X26<>"",_xlfn.XLOOKUP(X26,[1]ModifierDes!$B:$B,[1]ModifierDes!$A:$A,""),""),"") | AL26: =IF(S26="","",_xlfn.CONCAT("[",S26,"]")) | AM26: =IF(U26="","",_xlfn.CONCAT("[",U26,"]")) | AN26: =IF(W26="","",_xlfn.CONCAT("[",W26,"]")) | AO26: =IF(Y26="","",_xlfn.CONCAT("[",Y26,"]")) | AP26: =IFERROR(IF(Z26<>"",_xlfn.XLOOKUP(Z26,[1]StuntDes!$B:$B,[1]StuntDes!$A:$A,""),""),"") | AQ26: =IFERROR(IF(AA26<>"",_xlfn.XLOOKUP(AA26,[1]StuntDes!$B:$B,[1]StuntDes!$A:$A,""),""),"")
A27: =C27*10+D27 -> 50405 | B27: 小炎龙-星级5 | C27: 5040 | D27: 5 | G27: =_xlfn.TEXTJOIN("|",TRUE,AH27:AJ27) | H27: =IF(R27="","",_xlfn.CONCAT("[",_xlfn.TEXTJOIN(",",TRUE,AL27:AO27),"]")) | I27: =_xlfn.TEXTJOIN("|",TRUE,AP27:AQ27) | J27: =IF(AB27="","",_xlfn.CONCAT("[",_xlfn.TEXTJOIN(",",TRUE,AE27:AG27),"]")) -> [[10304,0.22],[11007,0.36],[10300,0.1]] | K27: =_xlfn.XLOOKUP(C27,Pet!A:A,Pet!E:E) -> R-火焰 | L27: 火焰伤害提高 | M27: 0.22 | N27: 点燃效果比例 | O27: 0.36 | P27: 全局伤害提高 | Q27: 0.1 | AB27: =IFERROR(IF(L27<>"",_xlfn.XLOOKUP(L27,[1]AttributeName!$C:$C,[1]AttributeName!$B:$B,""),""),"") -> 10304 | AC27: =IFERROR(IF(N27<>"",_xlfn.XLOOKUP(N27,[1]AttributeName!$C:$C,[1]AttributeName!$B:$B,""),""),"") -> 11007 | AD27: =IFERROR(IF(P27<>"",_xlfn.XLOOKUP(P27,[1]AttributeName!$C:$C,[1]AttributeName!$B:$B,""),""),"") -> 10300 | AE27: =IF(AB27="","",_xlfn.CONCAT("[",AB27,",",M27,"]")) -> [10304,0.22] | AF27: =IF(AC27="","",_xlfn.CONCAT("[",AC27,",",O27,"]")) -> [11007,0.36] | AG27: =IF(AD27="","",_xlfn.CONCAT("[",AD27,",",Q27,"]")) -> [10300,0.1] | AH27: =IFERROR(IF(R27<>"",_xlfn.XLOOKUP(R27,[1]ModifierDes!$B:$B,[1]ModifierDes!$A:$A,""),""),"") | AI27: =IFERROR(IF(T27<>"",_xlfn.XLOOKUP(T27,[1]ModifierDes!$B:$B,[1]ModifierDes!$A:$A,""),""),"") | AJ27: =IFERROR(IF(V27<>"",_xlfn.XLOOKUP(V27,[1]ModifierDes!$B:$B,[1]ModifierDes!$A:$A,""),""),"") | AK27: =IFERROR(IF(X27<>"",_xlfn.XLOOKUP(X27,[1]ModifierDes!$B:$B,[1]ModifierDes!$A:$A,""),""),"") | AL27: =IF(S27="","",_xlfn.CONCAT("[",S27,"]")) | AM27: =IF(U27="","",_xlfn.CONCAT("[",U27,"]")) | AN27: =IF(W27="","",_xlfn.CONCAT("[",W27,"]")) | AO27: =IF(Y27="","",_xlfn.CONCAT("[",Y27,"]")) | AP27: =IFERROR(IF(Z27<>"",_xlfn.XLOOKUP(Z27,[1]StuntDes!$B:$B,[1]StuntDes!$A:$A,""),""),"") | AQ27: =IFERROR(IF(AA27<>"",_xlfn.XLOOKUP(AA27,[1]StuntDes!$B:$B,[1]StuntDes!$A:$A,""),""),"")
A28: =C28*10+D28 -> 50500 | B28: 半兽人-星级0 | C28: 5050 | D28: 0 | E28: ="[["&C28+10000&",1]]" -> [[15050,1]] | G28: =_xlfn.TEXTJOIN("|",TRUE,AH28:AJ28) -> 10066|10031 | H28: =IF(R28="","",_xlfn.CONCAT("[",_xlfn.TEXTJOIN(",",TRUE,AL28:AO28),"]")) -> [[0.07],[0.01]] | I28: =_xlfn.TEXTJOIN("|",TRUE,AP28:AQ28) | J28: =IF(AB28="","",_xlfn.CONCAT("[",_xlfn.TEXTJOIN(",",TRUE,AE28:AG28),"]")) | K28: =_xlfn.XLOOKUP(C28,Pet!A:A,Pet!E:E) -> R-攻击 | R28: 攻击伤害提高 | S28: 0.07 | T28: 攻击速度提高 | U28: 0.01 | AB28: =IFERROR(IF(L28<>"",_xlfn.XLOOKUP(L28,[1]AttributeName!$C:$C,[1]AttributeName!$B:$B,""),""),"") | AC28: =IFERROR(IF(N28<>"",_xlfn.XLOOKUP(N28,[1]AttributeName!$C:$C,[1]AttributeName!$B:$B,""),""),"") | AD28: =IFERROR(IF(P28<>"",_xlfn.XLOOKUP(P28,[1]AttributeName!$C:$C,[1]AttributeName!$B:$B,""),""),"") | AE28: =IF(AB28="","",_xlfn.CONCAT("[",AB28,",",M28,"]")) | AF28: =IF(AC28="","",_xlfn.CONCAT("[",AC28,",",O28,"]")) | AG28: =IF(AD28="","",_xlfn.CONCAT("[",AD28,",",Q28,"]")) | AH28: =IFERROR(IF(R28<>"",_xlfn.XLOOKUP(R28,[1]ModifierDes!$B:$B,[1]ModifierDes!$A:$A,""),""),"") -> 10066 | AI28: =IFERROR(IF(T28<>"",_xlfn.XLOOKUP(T28,[1]ModifierDes!$B:$B,[1]ModifierDes!$A:$A,""),""),"") -> 10031 | AJ28: =IFERROR(IF(V28<>"",_xlfn.XLOOKUP(V28,[1]ModifierDes!$B:$B,[1]ModifierDes!$A:$A,""),""),"") | AK28: =IFERROR(IF(X28<>"",_xlfn.XLOOKUP(X28,[1]ModifierDes!$B:$B,[1]ModifierDes!$A:$A,""),""),"") | AL28: =IF(S28="","",_xlfn.CONCAT("[",S28,"]")) -> [0.07] | AM28: =IF(U28="","",_xlfn.CONCAT("[",U28,"]")) -> [0.01] | AN28: =IF(W28="","",_xlfn.CONCAT("[",W28,"]")) | AO28: =IF(Y28="","",_xlfn.CONCAT("[",Y28,"]")) | AP28: =IFERROR(IF(Z28<>"",_xlfn.XLOOKUP(Z28,[1]StuntDes!$B:$B,[1]StuntDes!$A:$A,""),""),"") | AQ28: =IFERROR(IF(AA28<>"",_xlfn.XLOOKUP(AA28,[1]StuntDes!$B:$B,[1]StuntDes!$A:$A,""),""),"")
A29: =C29*10+D29 -> 50501 | B29: 半兽人-星级1 | C29: 5050 | D29: 1 | E29: ="[["&C29+10000&",1]]" -> [[15050,1]] | G29: =_xlfn.TEXTJOIN("|",TRUE,AH29:AJ29) -> 10066|10031 | H29: =IF(R29="","",_xlfn.CONCAT("[",_xlfn.TEXTJOIN(",",TRUE,AL29:AO29),"]")) -> [[0.11],[0.01]] | I29: =_xlfn.TEXTJOIN("|",TRUE,AP29:AQ29) | J29: =IF(AB29="","",_xlfn.CONCAT("[",_xlfn.TEXTJOIN(",",TRUE,AE29:AG29),"]")) | K29: =_xlfn.XLOOKUP(C29,Pet!A:A,Pet!E:E) -> R-攻击 | R29: 攻击伤害提高 | S29: 0.11 | T29: 攻击速度提高 | U29: 0.01 | AB29: =IFERROR(IF(L29<>"",_xlfn.XLOOKUP(L29,[1]AttributeName!$C:$C,[1]AttributeName!$B:$B,""),""),"") | AC29: =IFERROR(IF(N29<>"",_xlfn.XLOOKUP(N29,[1]AttributeName!$C:$C,[1]AttributeName!$B:$B,""),""),"") | AD29: =IFERROR(IF(P29<>"",_xlfn.XLOOKUP(P29,[1]AttributeName!$C:$C,[1]AttributeName!$B:$B,""),""),"") | AE29: =IF(AB29="","",_xlfn.CONCAT("[",AB29,",",M29,"]")) | AF29: =IF(AC29="","",_xlfn.CONCAT("[",AC29,",",O29,"]")) | AG29: =IF(AD29="","",_xlfn.CONCAT("[",AD29,",",Q29,"]")) | AH29: =IFERROR(IF(R29<>"",_xlfn.XLOOKUP(R29,[1]ModifierDes!$B:$B,[1]ModifierDes!$A:$A,""),""),"") -> 10066 | AI29: =IFERROR(IF(T29<>"",_xlfn.XLOOKUP(T29,[1]ModifierDes!$B:$B,[1]ModifierDes!$A:$A,""),""),"") -> 10031 | AJ29: =IFERROR(IF(V29<>"",_xlfn.XLOOKUP(V29,[1]ModifierDes!$B:$B,[1]ModifierDes!$A:$A,""),""),"") | AK29: =IFERROR(IF(X29<>"",_xlfn.XLOOKUP(X29,[1]ModifierDes!$B:$B,[1]ModifierDes!$A:$A,""),""),"") | AL29: =IF(S29="","",_xlfn.CONCAT("[",S29,"]")) -> [0.11] | AM29: =IF(U29="","",_xlfn.CONCAT("[",U29,"]")) -> [0.01] | AN29: =IF(W29="","",_xlfn.CONCAT("[",W29,"]")) | AO29: =IF(Y29="","",_xlfn.CONCAT("[",Y29,"]")) | AP29: =IFERROR(IF(Z29<>"",_xlfn.XLOOKUP(Z29,[1]StuntDes!$B:$B,[1]StuntDes!$A:$A,""),""),"") | AQ29: =IFERROR(IF(AA29<>"",_xlfn.XLOOKUP(AA29,[1]StuntDes!$B:$B,[1]StuntDes!$A:$A,""),""),"")
A30: =C30*10+D30 -> 50502 | B30: 半兽人-星级2 | C30: 5050 | D30: 2 | E30: ="[["&C30+10000&",1]]" -> [[15050,1]] | G30: =_xlfn.TEXTJOIN("|",TRUE,AH30:AJ30) -> 10066|10031 | H30: =IF(R30="","",_xlfn.CONCAT("[",_xlfn.TEXTJOIN(",",TRUE,AL30:AO30),"]")) -> [[0.11],[0.03]] | I30: =_xlfn.TEXTJOIN("|",TRUE,AP30:AQ30) | J30: =IF(AB30="","",_xlfn.CONCAT("[",_xlfn.TEXTJOIN(",",TRUE,AE30:AG30),"]")) | K30: =_xlfn.XLOOKUP(C30,Pet!A:A,Pet!E:E) -> R-攻击 | R30: 攻击伤害提高 | S30: 0.11 | T30: 攻击速度提高 | U30: 0.03 | AB30: =IFERROR(IF(L30<>"",_xlfn.XLOOKUP(L30,[1]AttributeName!$C:$C,[1]AttributeName!$B:$B,""),""),"") | AC30: =IFERROR(IF(N30<>"",_xlfn.XLOOKUP(N30,[1]AttributeName!$C:$C,[1]AttributeName!$B:$B,""),""),"") | AD30: =IFERROR(IF(P30<>"",_xlfn.XLOOKUP(P30,[1]AttributeName!$C:$C,[1]AttributeName!$B:$B,""),""),"") | AE30: =IF(AB30="","",_xlfn.CONCAT("[",AB30,",",M30,"]")) | AF30: =IF(AC30="","",_xlfn.CONCAT("[",AC30,",",O30,"]")) | AG30: =IF(AD30="","",_xlfn.CONCAT("[",AD30,",",Q30,"]")) | AH30: =IFERROR(IF(R30<>"",_xlfn.XLOOKUP(R30,[1]ModifierDes!$B:$B,[1]ModifierDes!$A:$A,""),""),"") -> 10066 | AI30: =IFERROR(IF(T30<>"",_xlfn.XLOOKUP(T30,[1]ModifierDes!$B:$B,[1]ModifierDes!$A:$A,""),""),"") -> 10031 | AJ30: =IFERROR(IF(V30<>"",_xlfn.XLOOKUP(V30,[1]ModifierDes!$B:$B,[1]ModifierDes!$A:$A,""),""),"") | AK30: =IFERROR(IF(X30<>"",_xlfn.XLOOKUP(X30,[1]ModifierDes!$B:$B,[1]ModifierDes!$A:$A,""),""),"") | AL30: =IF(S30="","",_xlfn.CONCAT("[",S30,"]")) -> [0.11] | AM30: =IF(U30="","",_xlfn.CONCAT("[",U30,"]")) -> [0.03] | AN30: =IF(W30="","",_xlfn.CONCAT("[",W30,"]")) | AO30: =IF(Y30="","",_xlfn.CONCAT("[",Y30,"]")) | AP30: =IFERROR(IF(Z30<>"",_xlfn.XLOOKUP(Z30,[1]StuntDes!$B:$B,[1]StuntDes!$A:$A,""),""),"") | AQ30: =IFERROR(IF(AA30<>"",_xlfn.XLOOKUP(AA30,[1]StuntDes!$B:$B,[1]StuntDes!$A:$A,""),""),"")
A31: =C31*10+D31 -> 50503 | B31: 半兽人-星级3 | C31: 5050 | D31: 3 | E31: ="[["&C31+10000&",1]]" -> [[15050,1]] | G31: =_xlfn.TEXTJOIN("|",TRUE,AH31:AJ31) -> 10066|10031 | H31: =IF(R31="","",_xlfn.CONCAT("[",_xlfn.TEXTJOIN(",",TRUE,AL31:AO31),"]")) -> [[0.11],[0.03]] | I31: =_xlfn.TEXTJOIN("|",TRUE,AP31:AQ31) | J31: =IF(AB31="","",_xlfn.CONCAT("[",_xlfn.TEXTJOIN(",",TRUE,AE31:AG31),"]")) -> [[10300,0.07]] | K31: =_xlfn.XLOOKUP(C31,Pet!A:A,Pet!E:E) -> R-攻击 | L31: 全局伤害提高 | M31: 0.07 | R31: 攻击伤害提高 | S31: 0.11 | T31: 攻击速度提高 | U31: 0.03 | AB31: =IFERROR(IF(L31<>"",_xlfn.XLOOKUP(L31,[1]AttributeName!$C:$C,[1]AttributeName!$B:$B,""),""),"") -> 10300 | AC31: =IFERROR(IF(N31<>"",_xlfn.XLOOKUP(N31,[1]AttributeName!$C:$C,[1]AttributeName!$B:$B,""),""),"") | AD31: =IFERROR(IF(P31<>"",_xlfn.XLOOKUP(P31,[1]AttributeName!$C:$C,[1]AttributeName!$B:$B,""),""),"") | AE31: =IF(AB31="","",_xlfn.CONCAT("[",AB31,",",M31,"]")) -> [10300,0.07] | AF31: =IF(AC31="","",_xlfn.CONCAT("[",AC31,",",O31,"]")) | AG31: =IF(AD31="","",_xlfn.CONCAT("[",AD31,",",Q31,"]")) | AH31: =IFERROR(IF(R31<>"",_xlfn.XLOOKUP(R31,[1]ModifierDes!$B:$B,[1]ModifierDes!$A:$A,""),""),"") -> 10066 | AI31: =IFERROR(IF(T31<>"",_xlfn.XLOOKUP(T31,[1]ModifierDes!$B:$B,[1]ModifierDes!$A:$A,""),""),"") -> 10031 | AJ31: =IFERROR(IF(V31<>"",_xlfn.XLOOKUP(V31,[1]ModifierDes!$B:$B,[1]ModifierDes!$A:$A,""),""),"") | AK31: =IFERROR(IF(X31<>"",_xlfn.XLOOKUP(X31,[1]ModifierDes!$B:$B,[1]ModifierDes!$A:$A,""),""),"") | AL31: =IF(S31="","",_xlfn.CONCAT("[",S31,"]")) -> [0.11] | AM31: =IF(U31="","",_xlfn.CONCAT("[",U31,"]")) -> [0.03] | AN31: =IF(W31="","",_xlfn.CONCAT("[",W31,"]")) | AO31: =IF(Y31="","",_xlfn.CONCAT("[",Y31,"]")) | AP31: =IFERROR(IF(Z31<>"",_xlfn.XLOOKUP(Z31,[1]StuntDes!$B:$B,[1]StuntDes!$A:$A,""),""),"") | AQ31: =IFERROR(IF(AA31<>"",_xlfn.XLOOKUP(AA31,[1]StuntDes!$B:$B,[1]StuntDes!$A:$A,""),""),"")
